Workbook

Sheet RESPOSTAS
A1: Carimbo de data/hora | B1: Data | C1: Setor | D1: 1. Sua demanda de trabalho é mal distribuída? Ocorre excesso de trabalho devido a isso? | E1: 2. Com qual frequência, acaba se encontrando sem tempo para completar todas as tarefas do seu trabalho? | F1: 3. Precisa trabalhar em um ritmo muito rápido? | G1: 4. O seu trabalho exige a sua atenção constante? | H1: 5. O seu trabalho exige que tome decisões difíceis? | I1: 6. O seu trabalho exige controle emocional? | J1: 7. No trabalho, sua função possui um certo nível de influência, no que diz respeito a hierarquia da empresa? | K1: 8. O seu trabalho exige que tenha iniciativa? | L1: 9. O seu trabalho permite o desenvolvimento de atividades novas? | M1: 10. No seu local de trabalho, é informado com antecedência sobre decisões importantes, mudanças ou planos para o futuro? | N1: 11. Recebe toda a informação de que necessita para fazer bem o seu trabalho? | O1: 12. Sabe exatamente quais são as suas responsabilidades? Realiza suas atividades de rotina sem precisar ser cobrado? | P1: 13. O seu trabalho é reconhecido e apreciado pela direção? | Q1: 14. É tratado de forma justa no seu local de trabalho? | R1: 15. Com que frequência recebe ajuda e apoio do seu superior imediato? | S1: 16. Existe um ambiente de trabalho amigável entre si e seus colegas de equipe? | T1: 17. É oferecido aos colaboradores, oportunidades de desenvolvimento? | U1: 18. Possui um bom planejamento das demandas diárias e mensais? | V1: 19. A gerência confia nos seus funcionários para fazer o seu trabalho de forma adequada? | W1: 20. Confia na informação imediata, que é transmitida pela gerência? | X1: 21. Os conflitos são resolvidos de uma forma justa? | Y1: 22. O trabalho é igualmente distribuído aos funcionários do setor? | Z1: 23. Sou sempre capaz de resolver problemas, caso esteja focado o suficiente. | AA1: 24. Seu trabalho é importante para você? | AB1: 25. Sente que seu trabalho é valorizado, e tem uma devida importância no resultado geral do setor? | AC1: 26. Sente que os problemas do seu trabalho são seus também? | AD1: 27. O quão satisfeito está com seu trabalho de uma forma geral? | AE1: 28. Sente-se preocupado em ficar desempregado (a)? | AF1: 29. Em geral, sente que sua saúde mental está: | AG1: 30. Sente que seu trabalho exige muita energia mental e/ou física, no qual acaba por afetar sua vida negativamente? | AH1: 31. Sente que seu trabalho exige muito do tempo do seu dia, a ponto de afetar a sua vida privada negativamente? | AI1: 32. Acordou várias vezes durante a noite e depois não conseguia adormecer novamente? | AJ1: 33. Fisicamente exausto? | AK1: 34. Emocionalmente exausto? | AL1: 35. Irritado? | AM1: 36. Ansioso? | AN1: 37. Triste? | AO1: 38. Tem sido alvo de insultos ou provocações verbais? | AP1: 39. Tem sido exposto a assédio sexual indesejado? | AQ1: 40. Tem sido exposto a ameaças de violência? | AR1: 41. Tem sido exposto a violência física?
A2: 46065.613 | B2: 46065 | C2: CREDENCIAMENTO, EXAMES, LIMPEZA, RECEPÇÃO, SECRETARIA | D2: 3 - Às vezes | E2: 3 - Às vezes | F2: 5 - Sempre | G2: 5 - Sempre | H2: 3 - Às vezes | I2: 5 - Sempre | J2: 4 - Frequentemente | K2: 5 - Sempre | L2: 5 - Sempre | M2: 5 - Sempre | N2: 4 - Frequentemente | O2: 5 - Sempre | P2: 4 - Frequentemente | Q2: 4 - Frequentemente | R2: 4 - Frequentemente | S2: 5 - Sempre | T2: 4 - Frequentemente | U2: 4 - Frequentemente | V2: 4 - Frequentemente | W2: 4 - Frequentemente | X2: 5 - Sempre | Y2: 4 - Frequentemente | Z2: 4 - Frequentemente | AA2: 5 - Extremamente | AB2: 4 - Muito | AC2: 4 - Muito | AD2: 4 - Muito | AE2: 2 - Um pouco | AF2: 3 - Boa | AG2: 3 - Moderadamente | AH2: 2 - Um pouco | AI2: 4 - Frequentemente | AJ2: 3 - Às vezes | AK2: 3 - Às vezes | AL2: 3 - Às vezes | AM2: 3 - Às vezes | AN2: 2 - Raramente | AO2: 1 - Nunca/ quase nunca | AP2: 1 - Nunca/ quase nunca | AQ2: 1 - Nunca/ quase nunca | AR2: 1 - Nunca/ quase nunca
A3: 46065.619 | B3: 32007 | C3: CREDENCIAMENTO, EXAMES, LIMPEZA, RECEPÇÃO, SECRETARIA | D3: 5 - Sempre | E3: 3 - Às vezes | F3: 5 - Sempre | G3: 5 - Sempre | H3: 3 - Às vezes | I3: 5 - Sempre | J3: 5 - Sempre | K3: 4 - Frequentemente | L3: 2 - Raramente | M3: 2 - Raramente | N3: 3 - Às vezes | O3: 5 - Sempre | P3: 3 - Às vezes | Q3: 5 - Sempre | R3: 3 - Às vezes | S3: 5 - Sempre | T3: 5 - Sempre | U3: 3 - Às vezes | V3: 5 - Sempre | W3: 4 - Frequentemente | X3: 3 - Às vezes | Y3: 4 - Frequentemente | Z3: 5 - Sempre | AA3: 5 - Extremamente | AB3: 4 - Muito | AC3: 4 - Muito | AD3: 3 - Moderadamente | AE3: 2 - Um pouco | AF3: 5 - Excelente | AG3: 3 - Moderadamente | AH3: 3 - Moderadamente | AI3: 1 - Nunca/ quase nunca | AJ3: 4 - Frequentemente | AK3: 2 - Raramente | AL3: 1 - Nunca/ quase nunca | AM3: 1 - Nunca/ quase nunca | AN3: 1 - Nunca/ quase nunca | AO3: 1 - Nunca/ quase nunca | AP3: 1 - Nunca/ quase nunca | AQ3: 1 - Nunca/ quase nunca | AR3: 1 - Nunca/ quase nunca
A4: 46065.624 | B4: 46065 | C4: CREDENCIAMENTO, EXAMES, LIMPEZA, RECEPÇÃO, SECRETARIA | D4: 3 - Às vezes | E4: 1 - Nunca/ quase nunca | F4: 2 - Raramente | G4: 5 - Sempre | H4: 3 - Às vezes | I4: 5 - Sempre | J4: 5 - Sempre | K4: 5 - Sempre | L4: 3 - Às vezes | M4: 5 - Sempre | N4: 5 - Sempre | O4: 5 - Sempre | P4: 5 - Sempre | Q4: 5 - Sempre | R4: 5 - Sempre | S4: 5 - Sempre | T4: 5 - Sempre | U4: 5 - Sempre | V4: 5 - Sempre | W4: 5- Sempre | X4: 5 - Sempre | Y4: 5 - Sempre | Z4: 5 - Sempre | AA4: 5 - Extremamente | AB4: 4 - Muito | AC4: 4 - Muito | AD4: 4 - Muito | AE4: 4 - Muito | AF4: 4 - Muito Boa | AG4: 1 - Não / Pouquíssimo | AH4: 1 - Não / Pouquíssimo | AI4: 2 - Raramente | AJ4: 2 - Raramente | AK4: 1 - Nunca/ quase nunca | AL4: 2 - Raramente | AM4: 1 - Nunca/ quase nunca | AN4: 1 - Nunca/ quase nunca | AO4: 1 - Nunca/ quase nunca | AP4: 1 - Nunca/ quase nunca | AQ4: 1 - Nunca/ quase nunca | AR4: 1 - Nunca/ quase nunca
A5: 46065.63 | B5: 46065 | C5: CREDENCIAMENTO, EXAMES, LIMPEZA, RECEPÇÃO, SECRETARIA | D5: 2 - Raramente | E5: 1 - Nunca/ quase nunca | F5: 1 - Nunca/ quase nunca | G5: 5 - Sempre | H5: 1 - Nunca/ quase nunca | I5: 1 - Nunca/ quase nunca | J5: 2 - Raramente | K5: 3 - Às vezes | L5: 2 - Raramente | M5: 4 - Frequentemente | N5: 5 - Sempre | O5: 3 - Às vezes | P5: 2 - Raramente | Q5: 4 - Frequentemente | R5: 5 - Sempre | S5: 5 - Sempre | T5: 4 - Frequentemente | U5: 4 - Frequentemente | V5: 4 - Frequentemente | W5: 4 - Frequentemente | X5: 4 - Frequentemente | Y5: 4 - Frequentemente | Z5: 3 - Às vezes | AA5: 4 - Muito | AB5: 5 - Extremamente | AC5: 3 - Moderadamente | AD5: 4 - Muito | AE5: 2 - Um pouco | AF5: 4 - Muito Boa | AG5: 1 - Não / Pouquíssimo | AH5: 1 - Não / Pouquíssimo | AI5: 1 - Nunca/ quase nunca | AJ5: 2 - Raramente | AK5: 1 - Nunca/ quase nunca | AL5: 2 - Raramente | AM5: 2 - Raramente | AN5: 2 - Raramente | AO5: 1 - Nunca/ quase nunca | AP5: 1 - Nunca/ quase nunca | AQ5: 1 - Nunca/ quase nunca | AR5: 1 - Nunca/ quase nunca
A6: 46065.69 | B6: 46065 | C6: CREDENCIAMENTO, EXAMES, LIMPEZA, RECEPÇÃO, SECRETARIA | D6: 1 - Nunca/ quase nunca | E6: 1 - Nunca/ quase nunca | F6: 3 - Às vezes | G6: 5 - Sempre | H6: 4 - Frequentemente | I6: 3 - Às vezes | J6: 1 - Nunca/ quase nunca | K6: 5 - Sempre | L6: 3 - Às vezes | M6: 4 - Frequentemente | N6: 4 - Frequentemente | O6: 5 - Sempre | P6: 5 - Sempre | Q6: 3 - Às vezes | R6: 5 - Sempre | S6: 4 - Frequentemente | T6: 3 - Às vezes | U6: 5 - Sempre | V6: 5 - Sempre | W6: 5- Sempre | X6: 5 - Sempre | Y6: 3 - Às vezes | Z6: 5 - Sempre | AA6: 5 - Extremamente | AB6: 5 - Extremamente | AC6: 4 - Muito | AD6: 3 - Moderadamente | AE6: 3 - Moderadamente | AF6: 5 - Excelente | AG6: 1 - Não / Pouquíssimo | AH6: 1 - Não / Pouquíssimo | AI6: 1 - Nunca/ quase nunca | AJ6: 3 - Às vezes | AK6: 2 - Raramente | AL6: 2 - Raramente | AM6: 2 - Raramente | AN6: 1 - Nunca/ quase nunca | AO6: 2 - Raramente | AP6: 1 - Nunca/ quase nunca | AQ6: 2 - Raramente | AR6: 1 - Nunca/ quase nunca
A7: 46065.634 | B7: 46065 | C7: TÉCNICO | D7: 3 - Às vezes | E7: 2 - Raramente | F7: 3 - Às vezes | G7: 5 - Sempre | H7: 4 - Frequentemente | I7: 4 - Frequentemente | J7: 1 - Nunca/ quase nunca | K7: 4 - Frequentemente | L7: 4 - Frequentemente | M7: 5 - Sempre | N7: 5 - Sempre | O7: 5 - Sempre | P7: 3 - Às vezes | Q7: 5 - Sempre | R7: 5 - Sempre | S7: 5 - Sempre | T7: 5 - Sempre | U7: 5 - Sempre | V7: 4 - Frequentemente | W7: 5- Sempre | X7: 4 - Frequentemente | Y7: 4 - Frequentemente | Z7: 5 - Sempre | AA7: 5 - Extremamente | AB7: 4 - Muito | AC7: 5 - Extremamente | AD7: 5 - Extremamente | AE7: 2 - Um pouco | AF7: 3 - Boa | AG7: 1 - Não / Pouquíssimo | AH7: 2 - Um pouco | AI7: 3 - Às vezes | AJ7: 4 - Frequentemente | AK7: 2 - Raramente | AL7: 2 - Raramente | AM7: 2 - Raramente | AN7: 2 - Raramente | AO7: 1 - Nunca/ quase nunca | AP7: 1 - Nunca/ quase nunca | AQ7: 1 - Nunca/ quase nunca | AR7: 1 - Nunca/ quase nunca
A8: 46065.641 | B8: 46065 | C8: TÉCNICO | D8: 2 - Raramente | E8: 2 - Raramente | F8: 4 - Frequentemente | G8: 5 - Sempre | H8: 1 - Nunca/ quase nunca | I8: 1 - Nunca/ quase nunca | J8: 1 - Nunca/ quase nunca | K8: 4 - Frequentemente | L8: 2 - Raramente | M8: 2 - Raramente | N8: 5 - Sempre | O8: 4 - Frequentemente | P8: 3 - Às vezes | Q8: 4 - Frequentemente | R8: 5 - Sempre | S8: 4 - Frequentemente | T8: 3 - Às vezes | U8: 3 - Às vezes | V8: 4 - Frequentemente | W8: 4 - Frequentemente | X8: 3 - Às vezes | Y8: 3 - Às vezes | Z8: 5 - Sempre | AA8: 4 - Muito | AB8: 5 - Extremamente | AC8: 5 - Extremamente | AD8: 4 - Muito | AE8: 1 - Nada/ quase nada | AF8: 5 - Excelente | AG8: 1 - Não / Pouquíssimo | AH8: 2 - Um pouco | AI8: 3 - Às vezes | AJ8: 2 - Raramente | AK8: 1 - Nunca/ quase nunca | AL8: 1 - Nunca/ quase nunca | AM8: 5 - Sempre | AN8: 3 - Às vezes | AO8: 1 - Nunca/ quase nunca | AP8: 1 - Nunca/ quase nunca | AQ8: 1 - Nunca/ quase nunca | AR8: 1 - Nunca/ quase nunca
A9: 46065.646 | B9: 46065 | C9: TÉCNICO | D9: 1 - Nunca/ quase nunca | E9: 1 - Nunca/ quase nunca | F9: 3 - Às vezes | G9: 5 - Sempre | H9: 2 - Raramente | I9: 2 - Raramente | J9: 1 - Nunca/ quase nunca | K9: 4 - Frequentemente | L9: 5 - Sempre | M9: 4 - Frequentemente | N9: 5 - Sempre | O9: 2 - Raramente | P9: 4 - Frequentemente | Q9: 5 - Sempre | R9: 5 - Sempre | S9: 5 - Sempre | T9: 4 - Frequentemente | U9: 4 - Frequentemente | V9: 5 - Sempre | W9: 4 - Frequentemente | X9: 5 - Sempre | Y9: 5 - Sempre | Z9: 5 - Sempre | AA9: 4 - Muito | AB9: 2 - Um pouco | AC9: 1 - Nada/ quase nada | AD9: 5 - Extremamente | AE9: 2 - Um pouco | AF9: 4 - Muito Boa | AG9: 1 - Não / Pouquíssimo | AH9: 1 - Não / Pouquíssimo | AI9: 5 - Sempre | AJ9: 2 - Raramente | AK9: 1 - Nunca/ quase nunca | AL9: 3 - Às vezes | AM9: 4 - Frequentemente | AN9: 1 - Nunca/ quase nunca | AO9: 1 - Nunca/ quase nunca | AP9: 1 - Nunca/ quase nunca | AQ9: 1 - Nunca/ quase nunca | AR9: 1 - Nunca/ quase nunca
A10: 46065.652 | B10: 46065 | C10: TÉCNICO | D10: 2 - Raramente | E10: 3 - Às vezes | F10: 3 - Às vezes | G10: 5 - Sempre | H10: 3 - Às vezes | I10: 4 - Frequentemente | J10: 3 - Às vezes | K10: 4 - Frequentemente | L10: 4 - Frequentemente | M10: 2 - Raramente | N10: 2 - Raramente | O10: 3 - Às vezes | P10: 3 - Às vezes | Q10: 4 - Frequentemente | R10: 3 - Às vezes | S10: 4 - Frequentemente | T10: 2 - Raramente | U10: 2 - Raramente | V10: 3 - Às vezes | W10: 3 - Às vezes | X10: 3 - Às vezes | Y10: 3 - Às vezes | Z10: 4 - Frequentemente | AA10: 4 - Muito | AB10: 3 - Moderadamente | AC10: 3 - Moderadamente | AD10: 3 - Moderadamente | AE10: 3 - Moderadamente | AF10: 4 - Muito Boa | AG10: 4 - Muito | AH10: 4 - Muito | AI10: 2 - Raramente | AJ10: 2 - Raramente | AK10: 1 - Nunca/ quase nunca | AL10: 1 - Nunca/ quase nunca | AM10: 2 - Raramente | AN10: 1 - Nunca/ quase nunca | AO10: 1 - Nunca/ quase nunca | AP10: 1 - Nunca/ quase nunca | AQ10: 1 - Nunca/ quase nunca | AR10: 1 - Nunca/ quase nunca
A11: 46065.656 | B11: 46065 | C11: TÉCNICO | D11: 4 - Frequentemente | E11: 4 - Frequentemente | F11: 3 - Às vezes | G11: 5 - Sempre | H11: 3 - Às vezes | I11: 4 - Frequentemente | J11: 2 - Raramente | K11: 5 - Sempre | L11: 4 - Frequentemente | M11: 2 - Raramente | N11: 3 - Às vezes | O11: 4 - Frequentemente | P11: 5 - Sempre | Q11: 4 - Frequentemente | R11: 4 - Frequentemente | S11: 4 - Frequentemente | T11: 4 - Frequentemente | U11: 3 - Às vezes | V11: 4 - Frequentemente | W11: 4 - Frequentemente | X11: 4 - Frequentemente | Y11: 2 - Raramente | Z11: 5 - Sempre | AA11: 4 - Muito | AB11: 4 - Muito | AC11: 5 - Extremamente | AD11: 3 - Moderadamente | AE11: 5 - Extremamente | AF11: 2 - Razoável | AG11: 3 - Moderadamente | AH11: 3 - Moderadamente | AI11: 2 - Raramente | AJ11: 4 - Frequentemente | AK11: 4 - Frequentemente | AL11: 4 - Frequentemente | AM11: 4 - Frequentemente | AN11: 4 - Frequentemente | AO11: 2 - Raramente | AP11: 1 - Nunca/ quase nunca | AQ11: 1 - Nunca/ quase nunca | AR11: 1 - Nunca/ quase nunca
A12: 46065.659 | B12: 46065 | C12: TÉCNICO | D12: 1 - Nunca/ quase nunca | E12: 3 - Às vezes | F12: 3 - Às vezes | G12: 5 - Sempre | H12: 4 - Frequentemente | I12: 2 - Raramente | J12: 4 - Frequentemente | K12: 5 - Sempre | L12: 5 - Sempre | M12: 5 - Sempre | N12: 2 - Raramente | O12: 5 - Sempre | P12: 5 - Sempre | Q12: 5 - Sempre | R12: 4 - Frequentemente | S12: 5 - Sempre | T12: 3 - Às vezes | U12: 5 - Sempre | V12: 5 - Sempre | W12: 5- Sempre | X12: 5 - Sempre | Y12: 5 - Sempre | Z12: 5 - Sempre | AA12: 5 - Extremamente | AB12: 4 - Muito | AC12: 5 - Extremamente | AD12: 5 - Extremamente | AE12: 1 - Nada/ quase nada | AF12: 4 - Muito Boa | AG12: 4 - Muito | AH12: 4 - Muito | AI12: 2 - Raramente | AJ12: 2 - Raramente | AK12: 1 - Nunca/ quase nunca | AL12: 3 - Às vezes | AM12: 3 - Às vezes | AN12: 1 - Nunca/ quase nunca | AO12: 1 - Nunca/ quase nunca | AP12: 1 - Nunca/ quase nunca | AQ12: 1 - Nunca/ quase nunca | AR12: 1 - Nunca/ quase nunca
A13: 46065.673 | B13: 46065 | C13: FINANCEIRO | D13: 2 - Raramente | E13: 1 - Nunca/ quase nunca | F13: 3 - Às vezes | G13: 5 - Sempre | H13: 1 - Nunca/ quase nunca | I13: 4 - Frequentemente | J13: 4 - Frequentemente | K13: 4 - Frequentemente | L13: 2 - Raramente | M13: 4 - Frequentemente | N13: 5 - Sempre | O13: 5 - Sempre | P13: 2 - Raramente | Q13: 5 - Sempre | R13: 5 - Sempre | S13: 5 - Sempre | T13: 5 - Sempre | U13: 5 - Sempre | V13: 5 - Sempre | W13: 5- Sempre | X13: 5 - Sempre | Y13: 5 - Sempre | Z13: 5 - Sempre | AA13: 4 - Muito | AB13: 4 - Muito | AC13: 5 - Extremamente | AD13: 5 - Extremamente | AE13: 4 - Muito | AF13: 4 - Muito Boa | AG13: 1 - Não / Pouquíssimo | AH13: 1 - Não / Pouquíssimo | AI13: 1 - Nunca/ quase nunca | AJ13: 1 - Nunca/ quase nunca | AK13: 1 - Nunca/ quase nunca | AL13: 2 - Raramente | AM13: 2 - Raramente | AN13: 2 - Raramente | AO13: 1 - Nunca/ quase nunca | AP13: 1 - Nunca/ quase nunca | AQ13: 1 - Nunca/ quase nunca | AR13: 1 - Nunca/ quase nunca
... A17: 46065.717 | B17: 46065 | C17: COMERCIAL | D17: 1 - Nunca/ quase nunca | E17: 2 - Raramente | F17: 2 - Raramente | G17: 5 - Sempre | H17: 2 - Raramente | I17: 2 - Raramente | J17: 1 - Nunca/ quase nunca | K17: 5 - Sempre | L17: 5 - Sempre | M17: 5 - Sempre | N17: 5 - Sempre | O17: 5 - Sempre | P17: 5 - Sempre | Q17: 5 - Sempre | R17: 5 - Sempre | S17: 5 - Sempre | T17: 5 - Sempre | U17: 5 - Sempre | V17: 5 - Sempre | W17: 5- Sempre | X17: 5 - Sempre | Y17: 5 - Sempre | Z17: 5 - Sempre | AA17: 5 - Extremamente | AB17: 4 - Muito | AC17: 5 - Extremamente | AD17: 5 - Extremamente | AE17: 2 - Um pouco | AF17: 5 - Excelente | AG17: 1 - Não / Pouquíssimo | AH17: 1 - Não / Pouquíssimo | AI17: 1 - Nunca/ quase nunca | AJ17: 2 - Raramente | AK17: 2 - Raramente | AL17: 2 - Raramente | AM17: 2 - Raramente | AN17: 2 - Raramente | AO17: 1 - Nunca/ quase nunca | AP17: 1 - Nunca/ quase nunca | AQ17: 1 - Nunca/ quase nunca | AR17: 1 - Nunca/ quase nunca

Sheet BaseCálculo
A1: MÉDIA GERAL | B1: MÉDIA TOTAL: | C1: {=ROUND(SUMPRODUCT(IFERROR(Auxiliar!D$1:D$300,0))/COUNT(Auxiliar!D$1:D$300),2)} -> 2.25 | D1: {=ROUND(SUMPRODUCT(IFERROR(Auxiliar!E$1:E$300,0))/COUNT(Auxiliar!E$1:E$300),2)} -> 2.13 | E1: {=ROUND(SUMPRODUCT(IFERROR(Auxiliar!F$1:F$300,0))/COUNT(Auxiliar!F$1:F$300),2)} -> 3 | F1: {=ROUND(SUMPRODUCT(IFERROR(Auxiliar!G$1:G$300,0))/COUNT(Auxiliar!G$1:G$300),2)} -> 4.94 | G1: {=ROUND(SUMPRODUCT(IFERROR(Auxiliar!H$1:H$300,0))/COUNT(Auxiliar!H$1:H$300),2)} -> 2.63 | H1: {=ROUND(SUMPRODUCT(IFERROR(Auxiliar!I$1:I$300,0))/COUNT(Auxiliar!I$1:I$300),2)} -> 3 | I1: {=ROUND(SUMPRODUCT(IFERROR(Auxiliar!J$1:J$300,0))/COUNT(Auxiliar!J$1:J$300),2)} -> 2.56 | J1: {=ROUND(SUMPRODUCT(IFERROR(Auxiliar!K$1:K$300,0))/COUNT(Auxiliar!K$1:K$300),2)} -> 4.38 | ... AQ1: {=ROUND(SUMPRODUCT(IFERROR(Auxiliar!AR$1:AR$300,0))/COUNT(Auxiliar!AR$1:AR$300),2)} -> 1
A2: =ROUND(AVERAGE(C1:AQ1),2) -> 3.22 | B2: SETORES: | C2: P1 | D2: P2 | E2: P3 | F2: P4 | G2: P5 | H2: P6 | I2: P7 | J2: P8 | K2: P9 | L2: P10 | M2: P11 | N2: P12 | O2: P13 | P2: P14 | Q2: P15 | R2: P16 | S2: P17 | T2: P18 | U2: P19 | V2: P20 | W2: P21 | X2: P22 | Y2: P23 | Z2: P24 | AA2: P25 | AB2: P26 | AC2: P27 | AD2: P28 | AE2: P29 | AF2: P30 | AG2: P31 | AH2: P32 | AI2: P33 | AJ2: P34 | AK2: P35 | AL2: P36 | AM2: P37 | AN2: P38 | AO2: P39 | AP2: P40 | AQ2: P41
A3: =IFERROR(IF(ROUND(AVERAGE(C3:AQ3,COUNT(C3:AQ3)),2)=0,"",ROUND(AVERAGE(C3:AQ3,COUNT(C3:AQ3)),2)),"") -> 4.14 | B3: {=_xlfn.UNIQUE(RESPOSTAS!C2:C300)} -> CREDENCIAMENTO, EXAMES, LIMPEZA, RECEPÇÃO, SECRETARIA | C3: =IFERROR(IF(ROUND(SUMIF(RESPOSTAS!$C$2:$C$300,$B$3,Auxiliar!D$1:D$300)/COUNTIF(RESPOSTAS!$C$2:$C$300,$B$3),2)=0,"",ROUND(SUMIF(RESPOSTAS!$C$2:$C$300,$B$3,Auxiliar!D$1:D$300)/COUNTIF(RESPOSTAS!$C$2:$C$300,$B$3),2)),"") -> 2.5 | D3: =IFERROR(IF(ROUND(SUMIF(RESPOSTAS!$C$2:$C$300,$B$3,Auxiliar!E$1:E$300)/COUNTIF(RESPOSTAS!$C$2:$C$300,$B$3),2)=0,"",ROUND(SUMIF(RESPOSTAS!$C$2:$C$300,$B$3,Auxiliar!E$1:E$300)/COUNTIF(RESPOSTAS!$C$2:$C$300,$B$3),2)),"") -> 1.67 | E3: =IFERROR(IF(ROUND(SUMIF(RESPOSTAS!$C$2:$C$300,$B$3,Auxiliar!F$1:F$300)/COUNTIF(RESPOSTAS!$C$2:$C$300,$B$3),2)=0,"",ROUND(SUMIF(RESPOSTAS!$C$2:$C$300,$B$3,Auxiliar!F$1:F$300)/COUNTIF(RESPOSTAS!$C$2:$C$300,$B$3),2)),"") -> 3.17 | F3: =IFERROR(IF(ROUND(SUMIF(RESPOSTAS!$C$2:$C$300,$B$3,Auxiliar!G$1:G$300)/COUNTIF(RESPOSTAS!$C$2:$C$300,$B$3),2)=0,"",ROUND(SUMIF(RESPOSTAS!$C$2:$C$300,$B$3,Auxiliar!G$1:G$300)/COUNTIF(RESPOSTAS!$C$2:$C$300,$B$3),2)),"") -> 5 | G3: =IFERROR(IF(ROUND(SUMIF(RESPOSTAS!$C$2:$C$300,$B$3,Auxiliar!H$1:H$300)/COUNTIF(RESPOSTAS!$C$2:$C$300,$B$3),2)=0,"",ROUND(SUMIF(RESPOSTAS!$C$2:$C$300,$B$3,Auxiliar!H$1:H$300)/COUNTIF(RESPOSTAS!$C$2:$C$300,$B$3),2)),"") -> 3 | H3: =IFERROR(IF(ROUND(SUMIF(RESPOSTAS!$C$2:$C$300,$B$3,Auxiliar!I$1:I$300)/COUNTIF(RESPOSTAS!$C$2:$C$300,$B$3),2)=0,"",ROUND(SUMIF(RESPOSTAS!$C$2:$C$300,$B$3,Auxiliar!I$1:I$300)/COUNTIF(RESPOSTAS!$C$2:$C$300,$B$3),2)),"") -> 3.67 | I3: =IFERROR(IF(ROUND(SUMIF(RESPOSTAS!$C$2:$C$300,$B$3,Auxiliar!J$1:J$300)/COUNTIF(RESPOSTAS!$C$2:$C$300,$B$3),2)=0,"",ROUND(SUMIF(RESPOSTAS!$C$2:$C$300,$B$3,Auxiliar!J$1:J$300)/COUNTIF(RESPOSTAS!$C$2:$C$300,$B$3),2)),"") -> 3 | J3: =IFERROR(IF(ROUND(SUMIF(RESPOSTAS!$C$2:$C$300,$B$3,Auxiliar!K$1:K$300)/COUNTIF(RESPOSTAS!$C$2:$C$300,$B$3),2)=0,"",ROUND(SUMIF(RESPOSTAS!$C$2:$C$300,$B$3,Auxiliar!K$1:K$300)/COUNTIF(RESPOSTAS!$C$2:$C$300,$B$3),2)),"") -> 4.5 | ... AQ3: =IFERROR(IF(ROUND(SUMIF(RESPOSTAS!$C$2:$C$300,$B$3,Auxiliar!AR$1:AR$300)/COUNTIF(RESPOSTAS!$C$2:$C$300,$B$3),2)=0,"",ROUND(SUMIF(RESPOSTAS!$C$2:$C$300,$B$3,Auxiliar!AR$1:AR$300)/COUNTIF(RESPOSTAS!$C$2:$C$300,$B$3),2)),"") -> 1
A4: =IFERROR(IF(ROUND(AVERAGE(C4:AQ4,COUNT(C4:AQ4)),2)=0,"",ROUND(AVERAGE(C4:AQ4,COUNT(C4:AQ4)),2)),"") -> 4.1 | B4: TÉCNICO | C4: =IFERROR(IF(ROUND(SUMIF(RESPOSTAS!$C$2:$C$300,$B$4,Auxiliar!D$1:D$300)/COUNTIF(RESPOSTAS!$C$2:$C$300,$B$4),2)=0,"",ROUND(SUMIF(RESPOSTAS!$C$2:$C$300,$B$4,Auxiliar!D$1:D$300)/COUNTIF(RESPOSTAS!$C$2:$C$300,$B$4),2)),"") -> 2.17 | D4: =IFERROR(IF(ROUND(SUMIF(RESPOSTAS!$C$2:$C$300,$B$4,Auxiliar!E$1:E$300)/COUNTIF(RESPOSTAS!$C$2:$C$300,$B$4),2)=0,"",ROUND(SUMIF(RESPOSTAS!$C$2:$C$300,$B$4,Auxiliar!E$1:E$300)/COUNTIF(RESPOSTAS!$C$2:$C$300,$B$4),2)),"") -> 2.5 | E4: =IFERROR(IF(ROUND(SUMIF(RESPOSTAS!$C$2:$C$300,$B$4,Auxiliar!F$1:F$300)/COUNTIF(RESPOSTAS!$C$2:$C$300,$B$4),2)=0,"",ROUND(SUMIF(RESPOSTAS!$C$2:$C$300,$B$4,Auxiliar!F$1:F$300)/COUNTIF(RESPOSTAS!$C$2:$C$300,$B$4),2)),"") -> 3.17 | F4: =IFERROR(IF(ROUND(SUMIF(RESPOSTAS!$C$2:$C$300,$B$4,Auxiliar!G$1:G$300)/COUNTIF(RESPOSTAS!$C$2:$C$300,$B$4),2)=0,"",ROUND(SUMIF(RESPOSTAS!$C$2:$C$300,$B$4,Auxiliar!G$1:G$300)/COUNTIF(RESPOSTAS!$C$2:$C$300,$B$4),2)),"") -> 5 | G4: =IFERROR(IF(ROUND(SUMIF(RESPOSTAS!$C$2:$C$300,$B$4,Auxiliar!H$1:H$300)/COUNTIF(RESPOSTAS!$C$2:$C$300,$B$4),2)=0,"",ROUND(SUMIF(RESPOSTAS!$C$2:$C$300,$B$4,Auxiliar!H$1:H$300)/COUNTIF(RESPOSTAS!$C$2:$C$300,$B$4),2)),"") -> 2.83 | H4: =IFERROR(IF(ROUND(SUMIF(RESPOSTAS!$C$2:$C$300,$B$4,Auxiliar!I$1:I$300)/COUNTIF(RESPOSTAS!$C$2:$C$300,$B$4),2)=0,"",ROUND(SUMIF(RESPOSTAS!$C$2:$C$300,$B$4,Auxiliar!I$1:I$300)/COUNTIF(RESPOSTAS!$C$2:$C$300,$B$4),2)),"") -> 2.83 | I4: =IFERROR(IF(ROUND(SUMIF(RESPOSTAS!$C$2:$C$300,$B$4,Auxiliar!J$1:J$300)/COUNTIF(RESPOSTAS!$C$2:$C$300,$B$4),2)=0,"",ROUND(SUMIF(RESPOSTAS!$C$2:$C$300,$B$4,Auxiliar!J$1:J$300)/COUNTIF(RESPOSTAS!$C$2:$C$300,$B$4),2)),"") -> 2 | J4: =IFERROR(IF(ROUND(SUMIF(RESPOSTAS!$C$2:$C$300,$B$4,Auxiliar!K$1:K$300)/COUNTIF(RESPOSTAS!$C$2:$C$300,$B$4),2)=0,"",ROUND(SUMIF(RESPOSTAS!$C$2:$C$300,$B$4,Auxiliar!K$1:K$300)/COUNTIF(RESPOSTAS!$C$2:$C$300,$B$4),2)),"") -> 4.33 | ... AQ4: =IFERROR(IF(ROUND(SUMIF(RESPOSTAS!$C$2:$C$300,$B$4,Auxiliar!AR$1:AR$300)/COUNTIF(RESPOSTAS!$C$2:$C$300,$B$4),2)=0,"",ROUND(SUMIF(RESPOSTAS!$C$2:$C$300,$B$4,Auxiliar!AR$1:AR$300)/COUNTIF(RESPOSTAS!$C$2:$C$300,$B$4),2)),"") -> 1
A5: =IFERROR(IF(ROUND(AVERAGE(C5:AQ5,COUNT(C5:AQ5)),2)=0,"",ROUND(AVERAGE(C5:AQ5,COUNT(C5:AQ5)),2)),"") -> 4.17 | B5: FINANCEIRO | C5: =IFERROR(IF(ROUND(SUMIF(RESPOSTAS!$C$2:$C$300,$B$5,Auxiliar!D$1:D$300)/COUNTIF(RESPOSTAS!$C$2:$C$300,$B$5),2)=0,"",ROUND(SUMIF(RESPOSTAS!$C$2:$C$300,$B$5,Auxiliar!D$1:D$300)/COUNTIF(RESPOSTAS!$C$2:$C$300,$B$5),2)),"") -> 2.5 | D5: =IFERROR(IF(ROUND(SUMIF(RESPOSTAS!$C$2:$C$300,$B$5,Auxiliar!E$1:E$300)/COUNTIF(RESPOSTAS!$C$2:$C$300,$B$5),2)=0,"",ROUND(SUMIF(RESPOSTAS!$C$2:$C$300,$B$5,Auxiliar!E$1:E$300)/COUNTIF(RESPOSTAS!$C$2:$C$300,$B$5),2)),"") -> 2 | E5: =IFERROR(IF(ROUND(SUMIF(RESPOSTAS!$C$2:$C$300,$B$5,Auxiliar!F$1:F$300)/COUNTIF(RESPOSTAS!$C$2:$C$300,$B$5),2)=0,"",ROUND(SUMIF(RESPOSTAS!$C$2:$C$300,$B$5,Auxiliar!F$1:F$300)/COUNTIF(RESPOSTAS!$C$2:$C$300,$B$5),2)),"") -> 2.5 | F5: =IFERROR(IF(ROUND(SUMIF(RESPOSTAS!$C$2:$C$300,$B$5,Auxiliar!G$1:G$300)/COUNTIF(RESPOSTAS!$C$2:$C$300,$B$5),2)=0,"",ROUND(SUMIF(RESPOSTAS!$C$2:$C$300,$B$5,Auxiliar!G$1:G$300)/COUNTIF(RESPOSTAS!$C$2:$C$300,$B$5),2)),"") -> 5 | G5: =IFERROR(IF(ROUND(SUMIF(RESPOSTAS!$C$2:$C$300,$B$5,Auxiliar!H$1:H$300)/COUNTIF(RESPOSTAS!$C$2:$C$300,$B$5),2)=0,"",ROUND(SUMIF(RESPOSTAS!$C$2:$C$300,$B$5,Auxiliar!H$1:H$300)/COUNTIF(RESPOSTAS!$C$2:$C$300,$B$5),2)),"") -> 2 | H5: =IFERROR(IF(ROUND(SUMIF(RESPOSTAS!$C$2:$C$300,$B$5,Auxiliar!I$1:I$300)/COUNTIF(RESPOSTAS!$C$2:$C$300,$B$5),2)=0,"",ROUND(SUMIF(RESPOSTAS!$C$2:$C$300,$B$5,Auxiliar!I$1:I$300)/COUNTIF(RESPOSTAS!$C$2:$C$300,$B$5),2)),"") -> 2.5 | I5: =IFERROR(IF(ROUND(SUMIF(RESPOSTAS!$C$2:$C$300,$B$5,Auxiliar!J$1:J$300)/COUNTIF(RESPOSTAS!$C$2:$C$300,$B$5),2)=0,"",ROUND(SUMIF(RESPOSTAS!$C$2:$C$300,$B$5,Auxiliar!J$1:J$300)/COUNTIF(RESPOSTAS!$C$2:$C$300,$B$5),2)),"") -> 4.5 | J5: =IFERROR(IF(ROUND(SUMIF(RESPOSTAS!$C$2:$C$300,$B$5,Auxiliar!K$1:K$300)/COUNTIF(RESPOSTAS!$C$2:$C$300,$B$5),2)=0,"",ROUND(SUMIF(RESPOSTAS!$C$2:$C$300,$B$5,Auxiliar!K$1:K$300)/COUNTIF(RESPOSTAS!$C$2:$C$300,$B$5),2)),"") -> 4.5 | ... AQ5: =IFERROR(IF(ROUND(SUMIF(RESPOSTAS!$C$2:$C$300,$B$5,Auxiliar!AR$1:AR$300)/COUNTIF(RESPOSTAS!$C$2:$C$300,$B$5),2)=0,"",ROUND(SUMIF(RESPOSTAS!$C$2:$C$300,$B$5,Auxiliar!AR$1:AR$300)/COUNTIF(RESPOSTAS!$C$2:$C$300,$B$5),2)),"") -> 1
A6: =IFERROR(IF(ROUND(AVERAGE(C6:AQ6,COUNT(C6:AQ6)),2)=0,"",ROUND(AVERAGE(C6:AQ6,COUNT(C6:AQ6)),2)),"") -> 4.08 | B6: COMERCIAL | C6: =IFERROR(IF(ROUND(SUMIF(RESPOSTAS!$C$2:$C$300,$B$6,Auxiliar!D$1:D$300)/COUNTIF(RESPOSTAS!$C$2:$C$300,$B$6),2)=0,"",ROUND(SUMIF(RESPOSTAS!$C$2:$C$300,$B$6,Auxiliar!D$1:D$300)/COUNTIF(RESPOSTAS!$C$2:$C$300,$B$6),2)),"") -> 1.5 | D6: =IFERROR(IF(ROUND(SUMIF(RESPOSTAS!$C$2:$C$300,$B$6,Auxiliar!E$1:E$300)/COUNTIF(RESPOSTAS!$C$2:$C$300,$B$6),2)=0,"",ROUND(SUMIF(RESPOSTAS!$C$2:$C$300,$B$6,Auxiliar!E$1:E$300)/COUNTIF(RESPOSTAS!$C$2:$C$300,$B$6),2)),"") -> 2.5 | E6: =IFERROR(IF(ROUND(SUMIF(RESPOSTAS!$C$2:$C$300,$B$6,Auxiliar!F$1:F$300)/COUNTIF(RESPOSTAS!$C$2:$C$300,$B$6),2)=0,"",ROUND(SUMIF(RESPOSTAS!$C$2:$C$300,$B$6,Auxiliar!F$1:F$300)/COUNTIF(RESPOSTAS!$C$2:$C$300,$B$6),2)),"") -> 2.5 | F6: =IFERROR(IF(ROUND(SUMIF(RESPOSTAS!$C$2:$C$300,$B$6,Auxiliar!G$1:G$300)/COUNTIF(RESPOSTAS!$C$2:$C$300,$B$6),2)=0,"",ROUND(SUMIF(RESPOSTAS!$C$2:$C$300,$B$6,Auxiliar!G$1:G$300)/COUNTIF(RESPOSTAS!$C$2:$C$300,$B$6),2)),"") -> 4.5 | G6: =IFERROR(IF(ROUND(SUMIF(RESPOSTAS!$C$2:$C$300,$B$6,Auxiliar!H$1:H$300)/COUNTIF(RESPOSTAS!$C$2:$C$300,$B$6),2)=0,"",ROUND(SUMIF(RESPOSTAS!$C$2:$C$300,$B$6,Auxiliar!H$1:H$300)/COUNTIF(RESPOSTAS!$C$2:$C$300,$B$6),2)),"") -> 1.5 | H6: =IFERROR(IF(ROUND(SUMIF(RESPOSTAS!$C$2:$C$300,$B$6,Auxiliar!I$1:I$300)/COUNTIF(RESPOSTAS!$C$2:$C$300,$B$6),2)=0,"",ROUND(SUMIF(RESPOSTAS!$C$2:$C$300,$B$6,Auxiliar!I$1:I$300)/COUNTIF(RESPOSTAS!$C$2:$C$300,$B$6),2)),"") -> 2 | I6: =IFERROR(IF(ROUND(SUMIF(RESPOSTAS!$C$2:$C$300,$B$6,Auxiliar!J$1:J$300)/COUNTIF(RESPOSTAS!$C$2:$C$300,$B$6),2)=0,"",ROUND(SUMIF(RESPOSTAS!$C$2:$C$300,$B$6,Auxiliar!J$1:J$300)/COUNTIF(RESPOSTAS!$C$2:$C$300,$B$6),2)),"") -> 1 | J6: =IFERROR(IF(ROUND(SUMIF(RESPOSTAS!$C$2:$C$300,$B$6,Auxiliar!K$1:K$300)/COUNTIF(RESPOSTAS!$C$2:$C$300,$B$6),2)=0,"",ROUND(SUMIF(RESPOSTAS!$C$2:$C$300,$B$6,Auxiliar!K$1:K$300)/COUNTIF(RESPOSTAS!$C$2:$C$300,$B$6),2)),"") -> 4 | ... AQ6: =IFERROR(IF(ROUND(SUMIF(RESPOSTAS!$C$2:$C$300,$B$6,Auxiliar!AR$1:AR$300)/COUNTIF(RESPOSTAS!$C$2:$C$300,$B$6),2)=0,"",ROUND(SUMIF(RESPOSTAS!$C$2:$C$300,$B$6,Auxiliar!AR$1:AR$300)/COUNTIF(RESPOSTAS!$C$2:$C$300,$B$6),2)),"") -> 1
A7: =IFERROR(IF(ROUND(AVERAGE(C7:AQ7,COUNT(C7:AQ7)),2)=0,"",ROUND(AVERAGE(C7:AQ7,COUNT(C7:AQ7)),2)),"") | B7: 0 | C7: =IFERROR(IF(ROUND(SUMIF(RESPOSTAS!$C$2:$C$300,$B$7,Auxiliar!D$1:D$300)/COUNTIF(RESPOSTAS!$C$2:$C$300,$B$7),2)=0,"",ROUND(SUMIF(RESPOSTAS!$C$2:$C$300,$B$7,Auxiliar!D$1:D$300)/COUNTIF(RESPOSTAS!$C$2:$C$300,$B$7),2)),"") | D7: =IFERROR(IF(ROUND(SUMIF(RESPOSTAS!$C$2:$C$300,$B$7,Auxiliar!E$1:E$300)/COUNTIF(RESPOSTAS!$C$2:$C$300,$B$7),2)=0,"",ROUND(SUMIF(RESPOSTAS!$C$2:$C$300,$B$7,Auxiliar!E$1:E$300)/COUNTIF(RESPOSTAS!$C$2:$C$300,$B$7),2)),"") | E7: =IFERROR(IF(ROUND(SUMIF(RESPOSTAS!$C$2:$C$300,$B$7,Auxiliar!F$1:F$300)/COUNTIF(RESPOSTAS!$C$2:$C$300,$B$7),2)=0,"",ROUND(SUMIF(RESPOSTAS!$C$2:$C$300,$B$7,Auxiliar!F$1:F$300)/COUNTIF(RESPOSTAS!$C$2:$C$300,$B$7),2)),"") | F7: =IFERROR(IF(ROUND(SUMIF(RESPOSTAS!$C$2:$C$300,$B$7,Auxiliar!G$1:G$300)/COUNTIF(RESPOSTAS!$C$2:$C$300,$B$7),2)=0,"",ROUND(SUMIF(RESPOSTAS!$C$2:$C$300,$B$7,Auxiliar!G$1:G$300)/COUNTIF(RESPOSTAS!$C$2:$C$300,$B$7),2)),"") | G7: =IFERROR(IF(ROUND(SUMIF(RESPOSTAS!$C$2:$C$300,$B$7,Auxiliar!H$1:H$300)/COUNTIF(RESPOSTAS!$C$2:$C$300,$B$7),2)=0,"",ROUND(SUMIF(RESPOSTAS!$C$2:$C$300,$B$7,Auxiliar!H$1:H$300)/COUNTIF(RESPOSTAS!$C$2:$C$300,$B$7),2)),"") | H7: =IFERROR(IF(ROUND(SUMIF(RESPOSTAS!$C$2:$C$300,$B$7,Auxiliar!I$1:I$300)/COUNTIF(RESPOSTAS!$C$2:$C$300,$B$7),2)=0,"",ROUND(SUMIF(RESPOSTAS!$C$2:$C$300,$B$7,Auxiliar!I$1:I$300)/COUNTIF(RESPOSTAS!$C$2:$C$300,$B$7),2)),"") | I7: =IFERROR(IF(ROUND(SUMIF(RESPOSTAS!$C$2:$C$300,$B$7,Auxiliar!J$1:J$300)/COUNTIF(RESPOSTAS!$C$2:$C$300,$B$7),2)=0,"",ROUND(SUMIF(RESPOSTAS!$C$2:$C$300,$B$7,Auxiliar!J$1:J$300)/COUNTIF(RESPOSTAS!$C$2:$C$300,$B$7),2)),"") | J7: =IFERROR(IF(ROUND(SUMIF(RESPOSTAS!$C$2:$C$300,$B$7,Auxiliar!K$1:K$300)/COUNTIF(RESPOSTAS!$C$2:$C$300,$B$7),2)=0,"",ROUND(SUMIF(RESPOSTAS!$C$2:$C$300,$B$7,Auxiliar!K$1:K$300)/COUNTIF(RESPOSTAS!$C$2:$C$300,$B$7),2)),"") | ... AQ7: =IFERROR(IF(ROUND(SUMIF(RESPOSTAS!$C$2:$C$300,$B$7,Auxiliar!AR$1:AR$300)/COUNTIF(RESPOSTAS!$C$2:$C$300,$B$7),2)=0,"",ROUND(SUMIF(RESPOSTAS!$C$2:$C$300,$B$7,Auxiliar!AR$1:AR$300)/COUNTIF(RESPOSTAS!$C$2:$C$300,$B$7),2)),"")
A8: =IFERROR(IF(ROUND(AVERAGE(C8:AQ8,COUNT(C8:AQ8)),2)=0,"",ROUND(AVERAGE(C8:AQ8,COUNT(C8:AQ8)),2)),"") | C8: =IFERROR(IF(ROUND(SUMIF(RESPOSTAS!$C$2:$C$300,$B$8,Auxiliar!D$1:D$300)/COUNTIF(RESPOSTAS!$C$2:$C$300,$B$8),2)=0,"",ROUND(SUMIF(RESPOSTAS!$C$2:$C$300,$B$8,Auxiliar!D$1:D$300)/COUNTIF(RESPOSTAS!$C$2:$C$300,$B$8),2)),"") | D8: =IFERROR(IF(ROUND(SUMIF(RESPOSTAS!$C$2:$C$300,$B$8,Auxiliar!E$1:E$300)/COUNTIF(RESPOSTAS!$C$2:$C$300,$B$8),2)=0,"",ROUND(SUMIF(RESPOSTAS!$C$2:$C$300,$B$8,Auxiliar!E$1:E$300)/COUNTIF(RESPOSTAS!$C$2:$C$300,$B$8),2)),"") | E8: =IFERROR(IF(ROUND(SUMIF(RESPOSTAS!$C$2:$C$300,$B$8,Auxiliar!F$1:F$300)/COUNTIF(RESPOSTAS!$C$2:$C$300,$B$8),2)=0,"",ROUND(SUMIF(RESPOSTAS!$C$2:$C$300,$B$8,Auxiliar!F$1:F$300)/COUNTIF(RESPOSTAS!$C$2:$C$300,$B$8),2)),"") | F8: =IFERROR(IF(ROUND(SUMIF(RESPOSTAS!$C$2:$C$300,$B$8,Auxiliar!G$1:G$300)/COUNTIF(RESPOSTAS!$C$2:$C$300,$B$8),2)=0,"",ROUND(SUMIF(RESPOSTAS!$C$2:$C$300,$B$8,Auxiliar!G$1:G$300)/COUNTIF(RESPOSTAS!$C$2:$C$300,$B$8),2)),"") | G8: =IFERROR(IF(ROUND(SUMIF(RESPOSTAS!$C$2:$C$300,$B$8,Auxiliar!H$1:H$300)/COUNTIF(RESPOSTAS!$C$2:$C$300,$B$8),2)=0,"",ROUND(SUMIF(RESPOSTAS!$C$2:$C$300,$B$8,Auxiliar!H$1:H$300)/COUNTIF(RESPOSTAS!$C$2:$C$300,$B$8),2)),"") | H8: =IFERROR(IF(ROUND(SUMIF(RESPOSTAS!$C$2:$C$300,$B$8,Auxiliar!I$1:I$300)/COUNTIF(RESPOSTAS!$C$2:$C$300,$B$8),2)=0,"",ROUND(SUMIF(RESPOSTAS!$C$2:$C$300,$B$8,Auxiliar!I$1:I$300)/COUNTIF(RESPOSTAS!$C$2:$C$300,$B$8),2)),"") | I8: =IFERROR(IF(ROUND(SUMIF(RESPOSTAS!$C$2:$C$300,$B$8,Auxiliar!J$1:J$300)/COUNTIF(RESPOSTAS!$C$2:$C$300,$B$8),2)=0,"",ROUND(SUMIF(RESPOSTAS!$C$2:$C$300,$B$8,Auxiliar!J$1:J$300)/COUNTIF(RESPOSTAS!$C$2:$C$300,$B$8),2)),"") | J8: =IFERROR(IF(ROUND(SUMIF(RESPOSTAS!$C$2:$C$300,$B$8,Auxiliar!K$1:K$300)/COUNTIF(RESPOSTAS!$C$2:$C$300,$B$8),2)=0,"",ROUND(SUMIF(RESPOSTAS!$C$2:$C$300,$B$8,Auxiliar!K$1:K$300)/COUNTIF(RESPOSTAS!$C$2:$C$300,$B$8),2)),"") | ... AQ8: =IFERROR(IF(ROUND(SUMIF(RESPOSTAS!$C$2:$C$300,$B$8,Auxiliar!AR$1:AR$300)/COUNTIF(RESPOSTAS!$C$2:$C$300,$B$8),2)=0,"",ROUND(SUMIF(RESPOSTAS!$C$2:$C$300,$B$8,Auxiliar!AR$1:AR$300)/COUNTIF(RESPOSTAS!$C$2:$C$300,$B$8),2)),"")
A9: =IFERROR(IF(ROUND(AVERAGE(C9:AQ9,COUNT(C9:AQ9)),2)=0,"",ROUND(AVERAGE(C9:AQ9,COUNT(C9:AQ9)),2)),"") | C9: =IFERROR(IF(ROUND(SUMIF(RESPOSTAS!$C$2:$C$300,$B$9,Auxiliar!D$1:D$300)/COUNTIF(RESPOSTAS!$C$2:$C$300,$B$9),2)=0,"",ROUND(SUMIF(RESPOSTAS!$C$2:$C$300,$B$9,Auxiliar!D$1:D$300)/COUNTIF(RESPOSTAS!$C$2:$C$300,$B$9),2)),"") | D9: =IFERROR(IF(ROUND(SUMIF(RESPOSTAS!$C$2:$C$300,$B$9,Auxiliar!E$1:E$300)/COUNTIF(RESPOSTAS!$C$2:$C$300,$B$9),2)=0,"",ROUND(SUMIF(RESPOSTAS!$C$2:$C$300,$B$9,Auxiliar!E$1:E$300)/COUNTIF(RESPOSTAS!$C$2:$C$300,$B$9),2)),"") | E9: =IFERROR(IF(ROUND(SUMIF(RESPOSTAS!$C$2:$C$300,$B$9,Auxiliar!F$1:F$300)/COUNTIF(RESPOSTAS!$C$2:$C$300,$B$9),2)=0,"",ROUND(SUMIF(RESPOSTAS!$C$2:$C$300,$B$9,Auxiliar!F$1:F$300)/COUNTIF(RESPOSTAS!$C$2:$C$300,$B$9),2)),"") | F9: =IFERROR(IF(ROUND(SUMIF(RESPOSTAS!$C$2:$C$300,$B$9,Auxiliar!G$1:G$300)/COUNTIF(RESPOSTAS!$C$2:$C$300,$B$9),2)=0,"",ROUND(SUMIF(RESPOSTAS!$C$2:$C$300,$B$9,Auxiliar!G$1:G$300)/COUNTIF(RESPOSTAS!$C$2:$C$300,$B$9),2)),"") | G9: =IFERROR(IF(ROUND(SUMIF(RESPOSTAS!$C$2:$C$300,$B$9,Auxiliar!H$1:H$300)/COUNTIF(RESPOSTAS!$C$2:$C$300,$B$9),2)=0,"",ROUND(SUMIF(RESPOSTAS!$C$2:$C$300,$B$9,Auxiliar!H$1:H$300)/COUNTIF(RESPOSTAS!$C$2:$C$300,$B$9),2)),"") | H9: =IFERROR(IF(ROUND(SUMIF(RESPOSTAS!$C$2:$C$300,$B$9,Auxiliar!I$1:I$300)/COUNTIF(RESPOSTAS!$C$2:$C$300,$B$9),2)=0,"",ROUND(SUMIF(RESPOSTAS!$C$2:$C$300,$B$9,Auxiliar!I$1:I$300)/COUNTIF(RESPOSTAS!$C$2:$C$300,$B$9),2)),"") | I9: =IFERROR(IF(ROUND(SUMIF(RESPOSTAS!$C$2:$C$300,$B$9,Auxiliar!J$1:J$300)/COUNTIF(RESPOSTAS!$C$2:$C$300,$B$9),2)=0,"",ROUND(SUMIF(RESPOSTAS!$C$2:$C$300,$B$9,Auxiliar!J$1:J$300)/COUNTIF(RESPOSTAS!$C$2:$C$300,$B$9),2)),"") | J9: =IFERROR(IF(ROUND(SUMIF(RESPOSTAS!$C$2:$C$300,$B$9,Auxiliar!K$1:K$300)/COUNTIF(RESPOSTAS!$C$2:$C$300,$B$9),2)=0,"",ROUND(SUMIF(RESPOSTAS!$C$2:$C$300,$B$9,Auxiliar!K$1:K$300)/COUNTIF(RESPOSTAS!$C$2:$C$300,$B$9),2)),"") | ... AQ9: =IFERROR(IF(ROUND(SUMIF(RESPOSTAS!$C$2:$C$300,$B$9,Auxiliar!AR$1:AR$300)/COUNTIF(RESPOSTAS!$C$2:$C$300,$B$9),2)=0,"",ROUND(SUMIF(RESPOSTAS!$C$2:$C$300,$B$9,Auxiliar!AR$1:AR$300)/COUNTIF(RESPOSTAS!$C$2:$C$300,$B$9),2)),"")
A10: =IFERROR(IF(ROUND(AVERAGE(C10:AQ10,COUNT(C10:AQ10)),2)=0,"",ROUND(AVERAGE(C10:AQ10,COUNT(C10:AQ10)),2)),"") | C10: =IFERROR(IF(ROUND(SUMIF(RESPOSTAS!$C$2:$C$300,$B$10,Auxiliar!D$1:D$300)/COUNTIF(RESPOSTAS!$C$2:$C$300,$B$10),2)=0,"",ROUND(SUMIF(RESPOSTAS!$C$2:$C$300,$B$10,Auxiliar!D$1:D$300)/COUNTIF(RESPOSTAS!$C$2:$C$300,$B$10),2)),"") | D10: =IFERROR(IF(ROUND(SUMIF(RESPOSTAS!$C$2:$C$300,$B$10,Auxiliar!E$1:E$300)/COUNTIF(RESPOSTAS!$C$2:$C$300,$B$10),2)=0,"",ROUND(SUMIF(RESPOSTAS!$C$2:$C$300,$B$10,Auxiliar!E$1:E$300)/COUNTIF(RESPOSTAS!$C$2:$C$300,$B$10),2)),"") | E10: =IFERROR(IF(ROUND(SUMIF(RESPOSTAS!$C$2:$C$300,$B$10,Auxiliar!F$1:F$300)/COUNTIF(RESPOSTAS!$C$2:$C$300,$B$10),2)=0,"",ROUND(SUMIF(RESPOSTAS!$C$2:$C$300,$B$10,Auxiliar!F$1:F$300)/COUNTIF(RESPOSTAS!$C$2:$C$300,$B$10),2)),"") | F10: =IFERROR(IF(ROUND(SUMIF(RESPOSTAS!$C$2:$C$300,$B$10,Auxiliar!G$1:G$300)/COUNTIF(RESPOSTAS!$C$2:$C$300,$B$10),2)=0,"",ROUND(SUMIF(RESPOSTAS!$C$2:$C$300,$B$10,Auxiliar!G$1:G$300)/COUNTIF(RESPOSTAS!$C$2:$C$300,$B$10),2)),"") | G10: =IFERROR(IF(ROUND(SUMIF(RESPOSTAS!$C$2:$C$300,$B$10,Auxiliar!H$1:H$300)/COUNTIF(RESPOSTAS!$C$2:$C$300,$B$10),2)=0,"",ROUND(SUMIF(RESPOSTAS!$C$2:$C$300,$B$10,Auxiliar!H$1:H$300)/COUNTIF(RESPOSTAS!$C$2:$C$300,$B$10),2)),"") | H10: =IFERROR(IF(ROUND(SUMIF(RESPOSTAS!$C$2:$C$300,$B$10,Auxiliar!I$1:I$300)/COUNTIF(RESPOSTAS!$C$2:$C$300,$B$10),2)=0,"",ROUND(SUMIF(RESPOSTAS!$C$2:$C$300,$B$10,Auxiliar!I$1:I$300)/COUNTIF(RESPOSTAS!$C$2:$C$300,$B$10),2)),"") | I10: =IFERROR(IF(ROUND(SUMIF(RESPOSTAS!$C$2:$C$300,$B$10,Auxiliar!J$1:J$300)/COUNTIF(RESPOSTAS!$C$2:$C$300,$B$10),2)=0,"",ROUND(SUMIF(RESPOSTAS!$C$2:$C$300,$B$10,Auxiliar!J$1:J$300)/COUNTIF(RESPOSTAS!$C$2:$C$300,$B$10),2)),"") | J10: =IFERROR(IF(ROUND(SUMIF(RESPOSTAS!$C$2:$C$300,$B$10,Auxiliar!K$1:K$300)/COUNTIF(RESPOSTAS!$C$2:$C$300,$B$10),2)=0,"",ROUND(SUMIF(RESPOSTAS!$C$2:$C$300,$B$10,Auxiliar!K$1:K$300)/COUNTIF(RESPOSTAS!$C$2:$C$300,$B$10),2)),"") | ... AQ10: =IFERROR(IF(ROUND(SUMIF(RESPOSTAS!$C$2:$C$300,$B$10,Auxiliar!AR$1:AR$300)/COUNTIF(RESPOSTAS!$C$2:$C$300,$B$10),2)=0,"",ROUND(SUMIF(RESPOSTAS!$C$2:$C$300,$B$10,Auxiliar!AR$1:AR$300)/COUNTIF(RESPOSTAS!$C$2:$C$300,$B$10),2)),"")
A11: =IFERROR(IF(ROUND(AVERAGE(C11:AQ11,COUNT(C11:AQ11)),2)=0,"",ROUND(AVERAGE(C11:AQ11,COUNT(C11:AQ11)),2)),"") | C11: =IFERROR(IF(ROUND(SUMIF(RESPOSTAS!$C$2:$C$300,$B$11,Auxiliar!D$1:D$300)/COUNTIF(RESPOSTAS!$C$2:$C$300,$B$11),2)=0,"",ROUND(SUMIF(RESPOSTAS!$C$2:$C$300,$B$11,Auxiliar!D$1:D$300)/COUNTIF(RESPOSTAS!$C$2:$C$300,$B$11),2)),"") | D11: =IFERROR(IF(ROUND(SUMIF(RESPOSTAS!$C$2:$C$300,$B$11,Auxiliar!E$1:E$300)/COUNTIF(RESPOSTAS!$C$2:$C$300,$B$11),2)=0,"",ROUND(SUMIF(RESPOSTAS!$C$2:$C$300,$B$11,Auxiliar!E$1:E$300)/COUNTIF(RESPOSTAS!$C$2:$C$300,$B$11),2)),"") | E11: =IFERROR(IF(ROUND(SUMIF(RESPOSTAS!$C$2:$C$300,$B$11,Auxiliar!F$1:F$300)/COUNTIF(RESPOSTAS!$C$2:$C$300,$B$11),2)=0,"",ROUND(SUMIF(RESPOSTAS!$C$2:$C$300,$B$11,Auxiliar!F$1:F$300)/COUNTIF(RESPOSTAS!$C$2:$C$300,$B$11),2)),"") | F11: =IFERROR(IF(ROUND(SUMIF(RESPOSTAS!$C$2:$C$300,$B$11,Auxiliar!G$1:G$300)/COUNTIF(RESPOSTAS!$C$2:$C$300,$B$11),2)=0,"",ROUND(SUMIF(RESPOSTAS!$C$2:$C$300,$B$11,Auxiliar!G$1:G$300)/COUNTIF(RESPOSTAS!$C$2:$C$300,$B$11),2)),"") | G11: =IFERROR(IF(ROUND(SUMIF(RESPOSTAS!$C$2:$C$300,$B$11,Auxiliar!H$1:H$300)/COUNTIF(RESPOSTAS!$C$2:$C$300,$B$11),2)=0,"",ROUND(SUMIF(RESPOSTAS!$C$2:$C$300,$B$11,Auxiliar!H$1:H$300)/COUNTIF(RESPOSTAS!$C$2:$C$300,$B$11),2)),"") | H11: =IFERROR(IF(ROUND(SUMIF(RESPOSTAS!$C$2:$C$300,$B$11,Auxiliar!I$1:I$300)/COUNTIF(RESPOSTAS!$C$2:$C$300,$B$11),2)=0,"",ROUND(SUMIF(RESPOSTAS!$C$2:$C$300,$B$11,Auxiliar!I$1:I$300)/COUNTIF(RESPOSTAS!$C$2:$C$300,$B$11),2)),"") | I11: =IFERROR(IF(ROUND(SUMIF(RESPOSTAS!$C$2:$C$300,$B$11,Auxiliar!J$1:J$300)/COUNTIF(RESPOSTAS!$C$2:$C$300,$B$11),2)=0,"",ROUND(SUMIF(RESPOSTAS!$C$2:$C$300,$B$11,Auxiliar!J$1:J$300)/COUNTIF(RESPOSTAS!$C$2:$C$300,$B$11),2)),"") | J11: =IFERROR(IF(ROUND(SUMIF(RESPOSTAS!$C$2:$C$300,$B$11,Auxiliar!K$1:K$300)/COUNTIF(RESPOSTAS!$C$2:$C$300,$B$11),2)=0,"",ROUND(SUMIF(RESPOSTAS!$C$2:$C$300,$B$11,Auxiliar!K$1:K$300)/COUNTIF(RESPOSTAS!$C$2:$C$300,$B$11),2)),"") | ... AQ11: =IFERROR(IF(ROUND(SUMIF(RESPOSTAS!$C$2:$C$300,$B$11,Auxiliar!AR$1:AR$300)/COUNTIF(RESPOSTAS!$C$2:$C$300,$B$11),2)=0,"",ROUND(SUMIF(RESPOSTAS!$C$2:$C$300,$B$11,Auxiliar!AR$1:AR$300)/COUNTIF(RESPOSTAS!$C$2:$C$300,$B$11),2)),"")
A12: =IFERROR(IF(ROUND(AVERAGE(C12:AQ12,COUNT(C12:AQ12)),2)=0,"",ROUND(AVERAGE(C12:AQ12,COUNT(C12:AQ12)),2)),"") | C12: =IFERROR(IF(ROUND(SUMIF(RESPOSTAS!$C$2:$C$300,$B$12,Auxiliar!D$1:D$300)/COUNTIF(RESPOSTAS!$C$2:$C$300,$B$12),2)=0,"",ROUND(SUMIF(RESPOSTAS!$C$2:$C$300,$B$12,Auxiliar!D$1:D$300)/COUNTIF(RESPOSTAS!$C$2:$C$300,$B$12),2)),"") | D12: =IFERROR(IF(ROUND(SUMIF(RESPOSTAS!$C$2:$C$300,$B$12,Auxiliar!E$1:E$300)/COUNTIF(RESPOSTAS!$C$2:$C$300,$B$12),2)=0,"",ROUND(SUMIF(RESPOSTAS!$C$2:$C$300,$B$12,Auxiliar!E$1:E$300)/COUNTIF(RESPOSTAS!$C$2:$C$300,$B$12),2)),"") | E12: =IFERROR(IF(ROUND(SUMIF(RESPOSTAS!$C$2:$C$300,$B$12,Auxiliar!F$1:F$300)/COUNTIF(RESPOSTAS!$C$2:$C$300,$B$12),2)=0,"",ROUND(SUMIF(RESPOSTAS!$C$2:$C$300,$B$12,Auxiliar!F$1:F$300)/COUNTIF(RESPOSTAS!$C$2:$C$300,$B$12),2)),"") | F12: =IFERROR(IF(ROUND(SUMIF(RESPOSTAS!$C$2:$C$300,$B$12,Auxiliar!G$1:G$300)/COUNTIF(RESPOSTAS!$C$2:$C$300,$B$12),2)=0,"",ROUND(SUMIF(RESPOSTAS!$C$2:$C$300,$B$12,Auxiliar!G$1:G$300)/COUNTIF(RESPOSTAS!$C$2:$C$300,$B$12),2)),"") | G12: =IFERROR(IF(ROUND(SUMIF(RESPOSTAS!$C$2:$C$300,$B$12,Auxiliar!H$1:H$300)/COUNTIF(RESPOSTAS!$C$2:$C$300,$B$12),2)=0,"",ROUND(SUMIF(RESPOSTAS!$C$2:$C$300,$B$12,Auxiliar!H$1:H$300)/COUNTIF(RESPOSTAS!$C$2:$C$300,$B$12),2)),"") | H12: =IFERROR(IF(ROUND(SUMIF(RESPOSTAS!$C$2:$C$300,$B$12,Auxiliar!I$1:I$300)/COUNTIF(RESPOSTAS!$C$2:$C$300,$B$12),2)=0,"",ROUND(SUMIF(RESPOSTAS!$C$2:$C$300,$B$12,Auxiliar!I$1:I$300)/COUNTIF(RESPOSTAS!$C$2:$C$300,$B$12),2)),"") | I12: =IFERROR(IF(ROUND(SUMIF(RESPOSTAS!$C$2:$C$300,$B$12,Auxiliar!J$1:J$300)/COUNTIF(RESPOSTAS!$C$2:$C$300,$B$12),2)=0,"",ROUND(SUMIF(RESPOSTAS!$C$2:$C$300,$B$12,Auxiliar!J$1:J$300)/COUNTIF(RESPOSTAS!$C$2:$C$300,$B$12),2)),"") | J12: =IFERROR(IF(ROUND(SUMIF(RESPOSTAS!$C$2:$C$300,$B$12,Auxiliar!K$1:K$300)/COUNTIF(RESPOSTAS!$C$2:$C$300,$B$12),2)=0,"",ROUND(SUMIF(RESPOSTAS!$C$2:$C$300,$B$12,Auxiliar!K$1:K$300)/COUNTIF(RESPOSTAS!$C$2:$C$300,$B$12),2)),"") | ... AQ12: =IFERROR(IF(ROUND(SUMIF(RESPOSTAS!$C$2:$C$300,$B$12,Auxiliar!AR$1:AR$300)/COUNTIF(RESPOSTAS!$C$2:$C$300,$B$12),2)=0,"",ROUND(SUMIF(RESPOSTAS!$C$2:$C$300,$B$12,Auxiliar!AR$1:AR$300)/COUNTIF(RESPOSTAS!$C$2:$C$300,$B$12),2)),"")
A13: =IFERROR(IF(ROUND(AVERAGE(C13:AQ13,COUNT(C13:AQ13)),2)=0,"",ROUND(AVERAGE(C13:AQ13,COUNT(C13:AQ13)),2)),"") | C13: =IFERROR(IF(ROUND(SUMIF(RESPOSTAS!$C$2:$C$300,$B$13,Auxiliar!D$1:D$300)/COUNTIF(RESPOSTAS!$C$2:$C$300,$B$13),2)=0,"",ROUND(SUMIF(RESPOSTAS!$C$2:$C$300,$B$13,Auxiliar!D$1:D$300)/COUNTIF(RESPOSTAS!$C$2:$C$300,$B$13),2)),"") | D13: =IFERROR(IF(ROUND(SUMIF(RESPOSTAS!$C$2:$C$300,$B$13,Auxiliar!E$1:E$300)/COUNTIF(RESPOSTAS!$C$2:$C$300,$B$13),2)=0,"",ROUND(SUMIF(RESPOSTAS!$C$2:$C$300,$B$13,Auxiliar!E$1:E$300)/COUNTIF(RESPOSTAS!$C$2:$C$300,$B$13),2)),"") | E13: =IFERROR(IF(ROUND(SUMIF(RESPOSTAS!$C$2:$C$300,$B$13,Auxiliar!F$1:F$300)/COUNTIF(RESPOSTAS!$C$2:$C$300,$B$13),2)=0,"",ROUND(SUMIF(RESPOSTAS!$C$2:$C$300,$B$13,Auxiliar!F$1:F$300)/COUNTIF(RESPOSTAS!$C$2:$C$300,$B$13),2)),"") | F13: =IFERROR(IF(ROUND(SUMIF(RESPOSTAS!$C$2:$C$300,$B$13,Auxiliar!G$1:G$300)/COUNTIF(RESPOSTAS!$C$2:$C$300,$B$13),2)=0,"",ROUND(SUMIF(RESPOSTAS!$C$2:$C$300,$B$13,Auxiliar!G$1:G$300)/COUNTIF(RESPOSTAS!$C$2:$C$300,$B$13),2)),"") | G13: =IFERROR(IF(ROUND(SUMIF(RESPOSTAS!$C$2:$C$300,$B$13,Auxiliar!H$1:H$300)/COUNTIF(RESPOSTAS!$C$2:$C$300,$B$13),2)=0,"",ROUND(SUMIF(RESPOSTAS!$C$2:$C$300,$B$13,Auxiliar!H$1:H$300)/COUNTIF(RESPOSTAS!$C$2:$C$300,$B$13),2)),"") | H13: =IFERROR(IF(ROUND(SUMIF(RESPOSTAS!$C$2:$C$300,$B$13,Auxiliar!I$1:I$300)/COUNTIF(RESPOSTAS!$C$2:$C$300,$B$13),2)=0,"",ROUND(SUMIF(RESPOSTAS!$C$2:$C$300,$B$13,Auxiliar!I$1:I$300)/COUNTIF(RESPOSTAS!$C$2:$C$300,$B$13),2)),"") | I13: =IFERROR(IF(ROUND(SUMIF(RESPOSTAS!$C$2:$C$300,$B$13,Auxiliar!J$1:J$300)/COUNTIF(RESPOSTAS!$C$2:$C$300,$B$13),2)=0,"",ROUND(SUMIF(RESPOSTAS!$C$2:$C$300,$B$13,Auxiliar!J$1:J$300)/COUNTIF(RESPOSTAS!$C$2:$C$300,$B$13),2)),"") | J13: =IFERROR(IF(ROUND(SUMIF(RESPOSTAS!$C$2:$C$300,$B$13,Auxiliar!K$1:K$300)/COUNTIF(RESPOSTAS!$C$2:$C$300,$B$13),2)=0,"",ROUND(SUMIF(RESPOSTAS!$C$2:$C$300,$B$13,Auxiliar!K$1:K$300)/COUNTIF(RESPOSTAS!$C$2:$C$300,$B$13),2)),"") | ... AQ13: =IFERROR(IF(ROUND(SUMIF(RESPOSTAS!$C$2:$C$300,$B$13,Auxiliar!AR$1:AR$300)/COUNTIF(RESPOSTAS!$C$2:$C$300,$B$13),2)=0,"",ROUND(SUMIF(RESPOSTAS!$C$2:$C$300,$B$13,Auxiliar!AR$1:AR$300)/COUNTIF(RESPOSTAS!$C$2:$C$300,$B$13),2)),"")
A14: =IFERROR(IF(ROUND(AVERAGE(C14:AQ14,COUNT(C14:AQ14)),2)=0,"",ROUND(AVERAGE(C14:AQ14,COUNT(C14:AQ14)),2)),"") | C14: =IFERROR(IF(ROUND(SUMIF(RESPOSTAS!$C$2:$C$300,$B$14,Auxiliar!D$1:D$300)/COUNTIF(RESPOSTAS!$C$2:$C$300,$B$14),2)=0,"",ROUND(SUMIF(RESPOSTAS!$C$2:$C$300,$B$14,Auxiliar!D$1:D$300)/COUNTIF(RESPOSTAS!$C$2:$C$300,$B$14),2)),"") | D14: =IFERROR(IF(ROUND(SUMIF(RESPOSTAS!$C$2:$C$300,$B$14,Auxiliar!E$1:E$300)/COUNTIF(RESPOSTAS!$C$2:$C$300,$B$14),2)=0,"",ROUND(SUMIF(RESPOSTAS!$C$2:$C$300,$B$14,Auxiliar!E$1:E$300)/COUNTIF(RESPOSTAS!$C$2:$C$300,$B$14),2)),"") | E14: =IFERROR(IF(ROUND(SUMIF(RESPOSTAS!$C$2:$C$300,$B$14,Auxiliar!F$1:F$300)/COUNTIF(RESPOSTAS!$C$2:$C$300,$B$14),2)=0,"",ROUND(SUMIF(RESPOSTAS!$C$2:$C$300,$B$14,Auxiliar!F$1:F$300)/COUNTIF(RESPOSTAS!$C$2:$C$300,$B$14),2)),"") | F14: =IFERROR(IF(ROUND(SUMIF(RESPOSTAS!$C$2:$C$300,$B$14,Auxiliar!G$1:G$300)/COUNTIF(RESPOSTAS!$C$2:$C$300,$B$14),2)=0,"",ROUND(SUMIF(RESPOSTAS!$C$2:$C$300,$B$14,Auxiliar!G$1:G$300)/COUNTIF(RESPOSTAS!$C$2:$C$300,$B$14),2)),"") | G14: =IFERROR(IF(ROUND(SUMIF(RESPOSTAS!$C$2:$C$300,$B$14,Auxiliar!H$1:H$300)/COUNTIF(RESPOSTAS!$C$2:$C$300,$B$14),2)=0,"",ROUND(SUMIF(RESPOSTAS!$C$2:$C$300,$B$14,Auxiliar!H$1:H$300)/COUNTIF(RESPOSTAS!$C$2:$C$300,$B$14),2)),"") | H14: =IFERROR(IF(ROUND(SUMIF(RESPOSTAS!$C$2:$C$300,$B$14,Auxiliar!I$1:I$300)/COUNTIF(RESPOSTAS!$C$2:$C$300,$B$14),2)=0,"",ROUND(SUMIF(RESPOSTAS!$C$2:$C$300,$B$14,Auxiliar!I$1:I$300)/COUNTIF(RESPOSTAS!$C$2:$C$300,$B$14),2)),"") | I14: =IFERROR(IF(ROUND(SUMIF(RESPOSTAS!$C$2:$C$300,$B$14,Auxiliar!J$1:J$300)/COUNTIF(RESPOSTAS!$C$2:$C$300,$B$14),2)=0,"",ROUND(SUMIF(RESPOSTAS!$C$2:$C$300,$B$14,Auxiliar!J$1:J$300)/COUNTIF(RESPOSTAS!$C$2:$C$300,$B$14),2)),"") | J14: =IFERROR(IF(ROUND(SUMIF(RESPOSTAS!$C$2:$C$300,$B$14,Auxiliar!K$1:K$300)/COUNTIF(RESPOSTAS!$C$2:$C$300,$B$14),2)=0,"",ROUND(SUMIF(RESPOSTAS!$C$2:$C$300,$B$14,Auxiliar!K$1:K$300)/COUNTIF(RESPOSTAS!$C$2:$C$300,$B$14),2)),"") | ... AQ14: =IFERROR(IF(ROUND(SUMIF(RESPOSTAS!$C$2:$C$300,$B$14,Auxiliar!AR$1:AR$300)/COUNTIF(RESPOSTAS!$C$2:$C$300,$B$14),2)=0,"",ROUND(SUMIF(RESPOSTAS!$C$2:$C$300,$B$14,Auxiliar!AR$1:AR$300)/COUNTIF(RESPOSTAS!$C$2:$C$300,$B$14),2)),"")
A15: =IFERROR(IF(ROUND(AVERAGE(C15:AQ15,COUNT(C15:AQ15)),2)=0,"",ROUND(AVERAGE(C15:AQ15,COUNT(C15:AQ15)),2)),"") | C15: =IFERROR(IF(ROUND(SUMIF(RESPOSTAS!$C$2:$C$300,$B$15,Auxiliar!D$1:D$300)/COUNTIF(RESPOSTAS!$C$2:$C$300,$B$15),2)=0,"",ROUND(SUMIF(RESPOSTAS!$C$2:$C$300,$B$15,Auxiliar!D$1:D$300)/COUNTIF(RESPOSTAS!$C$2:$C$300,$B$15),2)),"") | D15: =IFERROR(IF(ROUND(SUMIF(RESPOSTAS!$C$2:$C$300,$B$15,Auxiliar!E$1:E$300)/COUNTIF(RESPOSTAS!$C$2:$C$300,$B$15),2)=0,"",ROUND(SUMIF(RESPOSTAS!$C$2:$C$300,$B$15,Auxiliar!E$1:E$300)/COUNTIF(RESPOSTAS!$C$2:$C$300,$B$15),2)),"") | E15: =IFERROR(IF(ROUND(SUMIF(RESPOSTAS!$C$2:$C$300,$B$15,Auxiliar!F$1:F$300)/COUNTIF(RESPOSTAS!$C$2:$C$300,$B$15),2)=0,"",ROUND(SUMIF(RESPOSTAS!$C$2:$C$300,$B$15,Auxiliar!F$1:F$300)/COUNTIF(RESPOSTAS!$C$2:$C$300,$B$15),2)),"") | F15: =IFERROR(IF(ROUND(SUMIF(RESPOSTAS!$C$2:$C$300,$B$15,Auxiliar!G$1:G$300)/COUNTIF(RESPOSTAS!$C$2:$C$300,$B$15),2)=0,"",ROUND(SUMIF(RESPOSTAS!$C$2:$C$300,$B$15,Auxiliar!G$1:G$300)/COUNTIF(RESPOSTAS!$C$2:$C$300,$B$15),2)),"") | G15: =IFERROR(IF(ROUND(SUMIF(RESPOSTAS!$C$2:$C$300,$B$15,Auxiliar!H$1:H$300)/COUNTIF(RESPOSTAS!$C$2:$C$300,$B$15),2)=0,"",ROUND(SUMIF(RESPOSTAS!$C$2:$C$300,$B$15,Auxiliar!H$1:H$300)/COUNTIF(RESPOSTAS!$C$2:$C$300,$B$15),2)),"") | H15: =IFERROR(IF(ROUND(SUMIF(RESPOSTAS!$C$2:$C$300,$B$15,Auxiliar!I$1:I$300)/COUNTIF(RESPOSTAS!$C$2:$C$300,$B$15),2)=0,"",ROUND(SUMIF(RESPOSTAS!$C$2:$C$300,$B$15,Auxiliar!I$1:I$300)/COUNTIF(RESPOSTAS!$C$2:$C$300,$B$15),2)),"") | I15: =IFERROR(IF(ROUND(SUMIF(RESPOSTAS!$C$2:$C$300,$B$15,Auxiliar!J$1:J$300)/COUNTIF(RESPOSTAS!$C$2:$C$300,$B$15),2)=0,"",ROUND(SUMIF(RESPOSTAS!$C$2:$C$300,$B$15,Auxiliar!J$1:J$300)/COUNTIF(RESPOSTAS!$C$2:$C$300,$B$15),2)),"") | J15: =IFERROR(IF(ROUND(SUMIF(RESPOSTAS!$C$2:$C$300,$B$15,Auxiliar!K$1:K$300)/COUNTIF(RESPOSTAS!$C$2:$C$300,$B$15),2)=0,"",ROUND(SUMIF(RESPOSTAS!$C$2:$C$300,$B$15,Auxiliar!K$1:K$300)/COUNTIF(RESPOSTAS!$C$2:$C$300,$B$15),2)),"") | ... AQ15: =IFERROR(IF(ROUND(SUMIF(RESPOSTAS!$C$2:$C$300,$B$15,Auxiliar!AR$1:AR$300)/COUNTIF(RESPOSTAS!$C$2:$C$300,$B$15),2)=0,"",ROUND(SUMIF(RESPOSTAS!$C$2:$C$300,$B$15,Auxiliar!AR$1:AR$300)/COUNTIF(RESPOSTAS!$C$2:$C$300,$B$15),2)),"")
A16: =IFERROR(IF(ROUND(AVERAGE(C16:AQ16,COUNT(C16:AQ16)),2)=0,"",ROUND(AVERAGE(C16:AQ16,COUNT(C16:AQ16)),2)),"") | C16: =IFERROR(IF(ROUND(SUMIF(RESPOSTAS!$C$2:$C$300,$B$16,Auxiliar!D$1:D$300)/COUNTIF(RESPOSTAS!$C$2:$C$300,$B$16),2)=0,"",ROUND(SUMIF(RESPOSTAS!$C$2:$C$300,$B$16,Auxiliar!D$1:D$300)/COUNTIF(RESPOSTAS!$C$2:$C$300,$B$16),2)),"") | D16: =IFERROR(IF(ROUND(SUMIF(RESPOSTAS!$C$2:$C$300,$B$16,Auxiliar!E$1:E$300)/COUNTIF(RESPOSTAS!$C$2:$C$300,$B$16),2)=0,"",ROUND(SUMIF(RESPOSTAS!$C$2:$C$300,$B$16,Auxiliar!E$1:E$300)/COUNTIF(RESPOSTAS!$C$2:$C$300,$B$16),2)),"") | E16: =IFERROR(IF(ROUND(SUMIF(RESPOSTAS!$C$2:$C$300,$B$16,Auxiliar!F$1:F$300)/COUNTIF(RESPOSTAS!$C$2:$C$300,$B$16),2)=0,"",ROUND(SUMIF(RESPOSTAS!$C$2:$C$300,$B$16,Auxiliar!F$1:F$300)/COUNTIF(RESPOSTAS!$C$2:$C$300,$B$16),2)),"") | F16: =IFERROR(IF(ROUND(SUMIF(RESPOSTAS!$C$2:$C$300,$B$16,Auxiliar!G$1:G$300)/COUNTIF(RESPOSTAS!$C$2:$C$300,$B$16),2)=0,"",ROUND(SUMIF(RESPOSTAS!$C$2:$C$300,$B$16,Auxiliar!G$1:G$300)/COUNTIF(RESPOSTAS!$C$2:$C$300,$B$16),2)),"") | G16: =IFERROR(IF(ROUND(SUMIF(RESPOSTAS!$C$2:$C$300,$B$16,Auxiliar!H$1:H$300)/COUNTIF(RESPOSTAS!$C$2:$C$300,$B$16),2)=0,"",ROUND(SUMIF(RESPOSTAS!$C$2:$C$300,$B$16,Auxiliar!H$1:H$300)/COUNTIF(RESPOSTAS!$C$2:$C$300,$B$16),2)),"") | H16: =IFERROR(IF(ROUND(SUMIF(RESPOSTAS!$C$2:$C$300,$B$16,Auxiliar!I$1:I$300)/COUNTIF(RESPOSTAS!$C$2:$C$300,$B$16),2)=0,"",ROUND(SUMIF(RESPOSTAS!$C$2:$C$300,$B$16,Auxiliar!I$1:I$300)/COUNTIF(RESPOSTAS!$C$2:$C$300,$B$16),2)),"") | I16: =IFERROR(IF(ROUND(SUMIF(RESPOSTAS!$C$2:$C$300,$B$16,Auxiliar!J$1:J$300)/COUNTIF(RESPOSTAS!$C$2:$C$300,$B$16),2)=0,"",ROUND(SUMIF(RESPOSTAS!$C$2:$C$300,$B$16,Auxiliar!J$1:J$300)/COUNTIF(RESPOSTAS!$C$2:$C$300,$B$16),2)),"") | J16: =IFERROR(IF(ROUND(SUMIF(RESPOSTAS!$C$2:$C$300,$B$16,Auxiliar!K$1:K$300)/COUNTIF(RESPOSTAS!$C$2:$C$300,$B$16),2)=0,"",ROUND(SUMIF(RESPOSTAS!$C$2:$C$300,$B$16,Auxiliar!K$1:K$300)/COUNTIF(RESPOSTAS!$C$2:$C$300,$B$16),2)),"") | ... AQ16: =IFERROR(IF(ROUND(SUMIF(RESPOSTAS!$C$2:$C$300,$B$16,Auxiliar!AR$1:AR$300)/COUNTIF(RESPOSTAS!$C$2:$C$300,$B$16),2)=0,"",ROUND(SUMIF(RESPOSTAS!$C$2:$C$300,$B$16,Auxiliar!AR$1:AR$300)/COUNTIF(RESPOSTAS!$C$2:$C$300,$B$16),2)),"")
A17: =IFERROR(IF(ROUND(AVERAGE(C17:AQ17,COUNT(C17:AQ17)),2)=0,"",ROUND(AVERAGE(C17:AQ17,COUNT(C17:AQ17)),2)),"") | C17: =IFERROR(IF(ROUND(SUMIF(RESPOSTAS!$C$2:$C$300,$B$17,Auxiliar!D$1:D$300)/COUNTIF(RESPOSTAS!$C$2:$C$300,$B$17),2)=0,"",ROUND(SUMIF(RESPOSTAS!$C$2:$C$300,$B$17,Auxiliar!D$1:D$300)/COUNTIF(RESPOSTAS!$C$2:$C$300,$B$17),2)),"") | D17: =IFERROR(IF(ROUND(SUMIF(RESPOSTAS!$C$2:$C$300,$B$17,Auxiliar!E$1:E$300)/COUNTIF(RESPOSTAS!$C$2:$C$300,$B$17),2)=0,"",ROUND(SUMIF(RESPOSTAS!$C$2:$C$300,$B$17,Auxiliar!E$1:E$300)/COUNTIF(RESPOSTAS!$C$2:$C$300,$B$17),2)),"") | E17: =IFERROR(IF(ROUND(SUMIF(RESPOSTAS!$C$2:$C$300,$B$17,Auxiliar!F$1:F$300)/COUNTIF(RESPOSTAS!$C$2:$C$300,$B$17),2)=0,"",ROUND(SUMIF(RESPOSTAS!$C$2:$C$300,$B$17,Auxiliar!F$1:F$300)/COUNTIF(RESPOSTAS!$C$2:$C$300,$B$17),2)),"") | F17: =IFERROR(IF(ROUND(SUMIF(RESPOSTAS!$C$2:$C$300,$B$17,Auxiliar!G$1:G$300)/COUNTIF(RESPOSTAS!$C$2:$C$300,$B$17),2)=0,"",ROUND(SUMIF(RESPOSTAS!$C$2:$C$300,$B$17,Auxiliar!G$1:G$300)/COUNTIF(RESPOSTAS!$C$2:$C$300,$B$17),2)),"") | G17: =IFERROR(IF(ROUND(SUMIF(RESPOSTAS!$C$2:$C$300,$B$17,Auxiliar!H$1:H$300)/COUNTIF(RESPOSTAS!$C$2:$C$300,$B$17),2)=0,"",ROUND(SUMIF(RESPOSTAS!$C$2:$C$300,$B$17,Auxiliar!H$1:H$300)/COUNTIF(RESPOSTAS!$C$2:$C$300,$B$17),2)),"") | H17: =IFERROR(IF(ROUND(SUMIF(RESPOSTAS!$C$2:$C$300,$B$17,Auxiliar!I$1:I$300)/COUNTIF(RESPOSTAS!$C$2:$C$300,$B$17),2)=0,"",ROUND(SUMIF(RESPOSTAS!$C$2:$C$300,$B$17,Auxiliar!I$1:I$300)/COUNTIF(RESPOSTAS!$C$2:$C$300,$B$17),2)),"") | I17: =IFERROR(IF(ROUND(SUMIF(RESPOSTAS!$C$2:$C$300,$B$17,Auxiliar!J$1:J$300)/COUNTIF(RESPOSTAS!$C$2:$C$300,$B$17),2)=0,"",ROUND(SUMIF(RESPOSTAS!$C$2:$C$300,$B$17,Auxiliar!J$1:J$300)/COUNTIF(RESPOSTAS!$C$2:$C$300,$B$17),2)),"") | J17: =IFERROR(IF(ROUND(SUMIF(RESPOSTAS!$C$2:$C$300,$B$17,Auxiliar!K$1:K$300)/COUNTIF(RESPOSTAS!$C$2:$C$300,$B$17),2)=0,"",ROUND(SUMIF(RESPOSTAS!$C$2:$C$300,$B$17,Auxiliar!K$1:K$300)/COUNTIF(RESPOSTAS!$C$2:$C$300,$B$17),2)),"") | ... AQ17: =IFERROR(IF(ROUND(SUMIF(RESPOSTAS!$C$2:$C$300,$B$17,Auxiliar!AR$1:AR$300)/COUNTIF(RESPOSTAS!$C$2:$C$300,$B$17),2)=0,"",ROUND(SUMIF(RESPOSTAS!$C$2:$C$300,$B$17,Auxiliar!AR$1:AR$300)/COUNTIF(RESPOSTAS!$C$2:$C$300,$B$17),2)),"")
A18: =IFERROR(IF(ROUND(AVERAGE(C18:AQ18,COUNT(C18:AQ18)),2)=0,"",ROUND(AVERAGE(C18:AQ18,COUNT(C18:AQ18)),2)),"") | C18: =IFERROR(IF(ROUND(SUMIF(RESPOSTAS!$C$2:$C$300,$B$18,Auxiliar!D$1:D$300)/COUNTIF(RESPOSTAS!$C$2:$C$300,$B$18),2)=0,"",ROUND(SUMIF(RESPOSTAS!$C$2:$C$300,$B$18,Auxiliar!D$1:D$300)/COUNTIF(RESPOSTAS!$C$2:$C$300,$B$18),2)),"") | D18: =IFERROR(IF(ROUND(SUMIF(RESPOSTAS!$C$2:$C$300,$B$18,Auxiliar!E$1:E$300)/COUNTIF(RESPOSTAS!$C$2:$C$300,$B$18),2)=0,"",ROUND(SUMIF(RESPOSTAS!$C$2:$C$300,$B$18,Auxiliar!E$1:E$300)/COUNTIF(RESPOSTAS!$C$2:$C$300,$B$18),2)),"") | E18: =IFERROR(IF(ROUND(SUMIF(RESPOSTAS!$C$2:$C$300,$B$18,Auxiliar!F$1:F$300)/COUNTIF(RESPOSTAS!$C$2:$C$300,$B$18),2)=0,"",ROUND(SUMIF(RESPOSTAS!$C$2:$C$300,$B$18,Auxiliar!F$1:F$300)/COUNTIF(RESPOSTAS!$C$2:$C$300,$B$18),2)),"") | F18: =IFERROR(IF(ROUND(SUMIF(RESPOSTAS!$C$2:$C$300,$B$18,Auxiliar!G$1:G$300)/COUNTIF(RESPOSTAS!$C$2:$C$300,$B$18),2)=0,"",ROUND(SUMIF(RESPOSTAS!$C$2:$C$300,$B$18,Auxiliar!G$1:G$300)/COUNTIF(RESPOSTAS!$C$2:$C$300,$B$18),2)),"") | G18: =IFERROR(IF(ROUND(SUMIF(RESPOSTAS!$C$2:$C$300,$B$18,Auxiliar!H$1:H$300)/COUNTIF(RESPOSTAS!$C$2:$C$300,$B$18),2)=0,"",ROUND(SUMIF(RESPOSTAS!$C$2:$C$300,$B$18,Auxiliar!H$1:H$300)/COUNTIF(RESPOSTAS!$C$2:$C$300,$B$18),2)),"") | H18: =IFERROR(IF(ROUND(SUMIF(RESPOSTAS!$C$2:$C$300,$B$18,Auxiliar!I$1:I$300)/COUNTIF(RESPOSTAS!$C$2:$C$300,$B$18),2)=0,"",ROUND(SUMIF(RESPOSTAS!$C$2:$C$300,$B$18,Auxiliar!I$1:I$300)/COUNTIF(RESPOSTAS!$C$2:$C$300,$B$18),2)),"") | I18: =IFERROR(IF(ROUND(SUMIF(RESPOSTAS!$C$2:$C$300,$B$18,Auxiliar!J$1:J$300)/COUNTIF(RESPOSTAS!$C$2:$C$300,$B$18),2)=0,"",ROUND(SUMIF(RESPOSTAS!$C$2:$C$300,$B$18,Auxiliar!J$1:J$300)/COUNTIF(RESPOSTAS!$C$2:$C$300,$B$18),2)),"") | J18: =IFERROR(IF(ROUND(SUMIF(RESPOSTAS!$C$2:$C$300,$B$18,Auxiliar!K$1:K$300)/COUNTIF(RESPOSTAS!$C$2:$C$300,$B$18),2)=0,"",ROUND(SUMIF(RESPOSTAS!$C$2:$C$300,$B$18,Auxiliar!K$1:K$300)/COUNTIF(RESPOSTAS!$C$2:$C$300,$B$18),2)),"") | ... AQ18: =IFERROR(IF(ROUND(SUMIF(RESPOSTAS!$C$2:$C$300,$B$18,Auxiliar!AR$1:AR$300)/COUNTIF(RESPOSTAS!$C$2:$C$300,$B$18),2)=0,"",ROUND(SUMIF(RESPOSTAS!$C$2:$C$300,$B$18,Auxiliar!AR$1:AR$300)/COUNTIF(RESPOSTAS!$C$2:$C$300,$B$18),2)),"")
A19: =IFERROR(IF(ROUND(AVERAGE(C19:AQ19,COUNT(C19:AQ19)),2)=0,"",ROUND(AVERAGE(C19:AQ19,COUNT(C19:AQ19)),2)),"") | C19: =IFERROR(IF(ROUND(SUMIF(RESPOSTAS!$C$2:$C$300,$B$19,Auxiliar!D$1:D$300)/COUNTIF(RESPOSTAS!$C$2:$C$300,$B$19),2)=0,"",ROUND(SUMIF(RESPOSTAS!$C$2:$C$300,$B$19,Auxiliar!D$1:D$300)/COUNTIF(RESPOSTAS!$C$2:$C$300,$B$19),2)),"") | D19: =IFERROR(IF(ROUND(SUMIF(RESPOSTAS!$C$2:$C$300,$B$19,Auxiliar!E$1:E$300)/COUNTIF(RESPOSTAS!$C$2:$C$300,$B$19),2)=0,"",ROUND(SUMIF(RESPOSTAS!$C$2:$C$300,$B$19,Auxiliar!E$1:E$300)/COUNTIF(RESPOSTAS!$C$2:$C$300,$B$19),2)),"") | E19: =IFERROR(IF(ROUND(SUMIF(RESPOSTAS!$C$2:$C$300,$B$19,Auxiliar!F$1:F$300)/COUNTIF(RESPOSTAS!$C$2:$C$300,$B$19),2)=0,"",ROUND(SUMIF(RESPOSTAS!$C$2:$C$300,$B$19,Auxiliar!F$1:F$300)/COUNTIF(RESPOSTAS!$C$2:$C$300,$B$19),2)),"") | F19: =IFERROR(IF(ROUND(SUMIF(RESPOSTAS!$C$2:$C$300,$B$19,Auxiliar!G$1:G$300)/COUNTIF(RESPOSTAS!$C$2:$C$300,$B$19),2)=0,"",ROUND(SUMIF(RESPOSTAS!$C$2:$C$300,$B$19,Auxiliar!G$1:G$300)/COUNTIF(RESPOSTAS!$C$2:$C$300,$B$19),2)),"") | G19: =IFERROR(IF(ROUND(SUMIF(RESPOSTAS!$C$2:$C$300,$B$19,Auxiliar!H$1:H$300)/COUNTIF(RESPOSTAS!$C$2:$C$300,$B$19),2)=0,"",ROUND(SUMIF(RESPOSTAS!$C$2:$C$300,$B$19,Auxiliar!H$1:H$300)/COUNTIF(RESPOSTAS!$C$2:$C$300,$B$19),2)),"") | H19: =IFERROR(IF(ROUND(SUMIF(RESPOSTAS!$C$2:$C$300,$B$19,Auxiliar!I$1:I$300)/COUNTIF(RESPOSTAS!$C$2:$C$300,$B$19),2)=0,"",ROUND(SUMIF(RESPOSTAS!$C$2:$C$300,$B$19,Auxiliar!I$1:I$300)/COUNTIF(RESPOSTAS!$C$2:$C$300,$B$19),2)),"") | I19: =IFERROR(IF(ROUND(SUMIF(RESPOSTAS!$C$2:$C$300,$B$19,Auxiliar!J$1:J$300)/COUNTIF(RESPOSTAS!$C$2:$C$300,$B$19),2)=0,"",ROUND(SUMIF(RESPOSTAS!$C$2:$C$300,$B$19,Auxiliar!J$1:J$300)/COUNTIF(RESPOSTAS!$C$2:$C$300,$B$19),2)),"") | J19: =IFERROR(IF(ROUND(SUMIF(RESPOSTAS!$C$2:$C$300,$B$19,Auxiliar!K$1:K$300)/COUNTIF(RESPOSTAS!$C$2:$C$300,$B$19),2)=0,"",ROUND(SUMIF(RESPOSTAS!$C$2:$C$300,$B$19,Auxiliar!K$1:K$300)/COUNTIF(RESPOSTAS!$C$2:$C$300,$B$19),2)),"") | ... AQ19: =IFERROR(IF(ROUND(SUMIF(RESPOSTAS!$C$2:$C$300,$B$19,Auxiliar!AR$1:AR$300)/COUNTIF(RESPOSTAS!$C$2:$C$300,$B$19),2)=0,"",ROUND(SUMIF(RESPOSTAS!$C$2:$C$300,$B$19,Auxiliar!AR$1:AR$300)/COUNTIF(RESPOSTAS!$C$2:$C$300,$B$19),2)),"")
A20: =IFERROR(IF(ROUND(AVERAGE(C20:AQ20,COUNT(C20:AQ20)),2)=0,"",ROUND(AVERAGE(C20:AQ20,COUNT(C20:AQ20)),2)),"") | C20: =IFERROR(IF(ROUND(SUMIF(RESPOSTAS!$C$2:$C$300,$B$20,Auxiliar!D$1:D$300)/COUNTIF(RESPOSTAS!$C$2:$C$300,$B$20),2)=0,"",ROUND(SUMIF(RESPOSTAS!$C$2:$C$300,$B$20,Auxiliar!D$1:D$300)/COUNTIF(RESPOSTAS!$C$2:$C$300,$B$20),2)),"") | D20: =IFERROR(IF(ROUND(SUMIF(RESPOSTAS!$C$2:$C$300,$B$20,Auxiliar!E$1:E$300)/COUNTIF(RESPOSTAS!$C$2:$C$300,$B$20),2)=0,"",ROUND(SUMIF(RESPOSTAS!$C$2:$C$300,$B$20,Auxiliar!E$1:E$300)/COUNTIF(RESPOSTAS!$C$2:$C$300,$B$20),2)),"") | E20: =IFERROR(IF(ROUND(SUMIF(RESPOSTAS!$C$2:$C$300,$B$20,Auxiliar!F$1:F$300)/COUNTIF(RESPOSTAS!$C$2:$C$300,$B$20),2)=0,"",ROUND(SUMIF(RESPOSTAS!$C$2:$C$300,$B$20,Auxiliar!F$1:F$300)/COUNTIF(RESPOSTAS!$C$2:$C$300,$B$20),2)),"") | F20: =IFERROR(IF(ROUND(SUMIF(RESPOSTAS!$C$2:$C$300,$B$20,Auxiliar!G$1:G$300)/COUNTIF(RESPOSTAS!$C$2:$C$300,$B$20),2)=0,"",ROUND(SUMIF(RESPOSTAS!$C$2:$C$300,$B$20,Auxiliar!G$1:G$300)/COUNTIF(RESPOSTAS!$C$2:$C$300,$B$20),2)),"") | G20: =IFERROR(IF(ROUND(SUMIF(RESPOSTAS!$C$2:$C$300,$B$20,Auxiliar!H$1:H$300)/COUNTIF(RESPOSTAS!$C$2:$C$300,$B$20),2)=0,"",ROUND(SUMIF(RESPOSTAS!$C$2:$C$300,$B$20,Auxiliar!H$1:H$300)/COUNTIF(RESPOSTAS!$C$2:$C$300,$B$20),2)),"") | H20: =IFERROR(IF(ROUND(SUMIF(RESPOSTAS!$C$2:$C$300,$B$20,Auxiliar!I$1:I$300)/COUNTIF(RESPOSTAS!$C$2:$C$300,$B$20),2)=0,"",ROUND(SUMIF(RESPOSTAS!$C$2:$C$300,$B$20,Auxiliar!I$1:I$300)/COUNTIF(RESPOSTAS!$C$2:$C$300,$B$20),2)),"") | I20: =IFERROR(IF(ROUND(SUMIF(RESPOSTAS!$C$2:$C$300,$B$20,Auxiliar!J$1:J$300)/COUNTIF(RESPOSTAS!$C$2:$C$300,$B$20),2)=0,"",ROUND(SUMIF(RESPOSTAS!$C$2:$C$300,$B$20,Auxiliar!J$1:J$300)/COUNTIF(RESPOSTAS!$C$2:$C$300,$B$20),2)),"") | J20: =IFERROR(IF(ROUND(SUMIF(RESPOSTAS!$C$2:$C$300,$B$20,Auxiliar!K$1:K$300)/COUNTIF(RESPOSTAS!$C$2:$C$300,$B$20),2)=0,"",ROUND(SUMIF(RESPOSTAS!$C$2:$C$300,$B$20,Auxiliar!K$1:K$300)/COUNTIF(RESPOSTAS!$C$2:$C$300,$B$20),2)),"") | ... AQ20: =IFERROR(IF(ROUND(SUMIF(RESPOSTAS!$C$2:$C$300,$B$20,Auxiliar!AR$1:AR$300)/COUNTIF(RESPOSTAS!$C$2:$C$300,$B$20),2)=0,"",ROUND(SUMIF(RESPOSTAS!$C$2:$C$300,$B$20,Auxiliar!AR$1:AR$300)/COUNTIF(RESPOSTAS!$C$2:$C$300,$B$20),2)),"")
A21: =IFERROR(IF(ROUND(AVERAGE(C21:AQ21,COUNT(C21:AQ21)),2)=0,"",ROUND(AVERAGE(C21:AQ21,COUNT(C21:AQ21)),2)),"") | C21: =IFERROR(IF(ROUND(SUMIF(RESPOSTAS!$C$2:$C$300,$B$21,Auxiliar!D$1:D$300)/COUNTIF(RESPOSTAS!$C$2:$C$300,$B$21),2)=0,"",ROUND(SUMIF(RESPOSTAS!$C$2:$C$300,$B$21,Auxiliar!D$1:D$300)/COUNTIF(RESPOSTAS!$C$2:$C$300,$B$21),2)),"") | D21: =IFERROR(IF(ROUND(SUMIF(RESPOSTAS!$C$2:$C$300,$B$21,Auxiliar!E$1:E$300)/COUNTIF(RESPOSTAS!$C$2:$C$300,$B$21),2)=0,"",ROUND(SUMIF(RESPOSTAS!$C$2:$C$300,$B$21,Auxiliar!E$1:E$300)/COUNTIF(RESPOSTAS!$C$2:$C$300,$B$21),2)),"") | E21: =IFERROR(IF(ROUND(SUMIF(RESPOSTAS!$C$2:$C$300,$B$21,Auxiliar!F$1:F$300)/COUNTIF(RESPOSTAS!$C$2:$C$300,$B$21),2)=0,"",ROUND(SUMIF(RESPOSTAS!$C$2:$C$300,$B$21,Auxiliar!F$1:F$300)/COUNTIF(RESPOSTAS!$C$2:$C$300,$B$21),2)),"") | F21: =IFERROR(IF(ROUND(SUMIF(RESPOSTAS!$C$2:$C$300,$B$21,Auxiliar!G$1:G$300)/COUNTIF(RESPOSTAS!$C$2:$C$300,$B$21),2)=0,"",ROUND(SUMIF(RESPOSTAS!$C$2:$C$300,$B$21,Auxiliar!G$1:G$300)/COUNTIF(RESPOSTAS!$C$2:$C$300,$B$21),2)),"") | G21: =IFERROR(IF(ROUND(SUMIF(RESPOSTAS!$C$2:$C$300,$B$21,Auxiliar!H$1:H$300)/COUNTIF(RESPOSTAS!$C$2:$C$300,$B$21),2)=0,"",ROUND(SUMIF(RESPOSTAS!$C$2:$C$300,$B$21,Auxiliar!H$1:H$300)/COUNTIF(RESPOSTAS!$C$2:$C$300,$B$21),2)),"") | H21: =IFERROR(IF(ROUND(SUMIF(RESPOSTAS!$C$2:$C$300,$B$21,Auxiliar!I$1:I$300)/COUNTIF(RESPOSTAS!$C$2:$C$300,$B$21),2)=0,"",ROUND(SUMIF(RESPOSTAS!$C$2:$C$300,$B$21,Auxiliar!I$1:I$300)/COUNTIF(RESPOSTAS!$C$2:$C$300,$B$21),2)),"") | I21: =IFERROR(IF(ROUND(SUMIF(RESPOSTAS!$C$2:$C$300,$B$21,Auxiliar!J$1:J$300)/COUNTIF(RESPOSTAS!$C$2:$C$300,$B$21),2)=0,"",ROUND(SUMIF(RESPOSTAS!$C$2:$C$300,$B$21,Auxiliar!J$1:J$300)/COUNTIF(RESPOSTAS!$C$2:$C$300,$B$21),2)),"") | J21: =IFERROR(IF(ROUND(SUMIF(RESPOSTAS!$C$2:$C$300,$B$21,Auxiliar!K$1:K$300)/COUNTIF(RESPOSTAS!$C$2:$C$300,$B$21),2)=0,"",ROUND(SUMIF(RESPOSTAS!$C$2:$C$300,$B$21,Auxiliar!K$1:K$300)/COUNTIF(RESPOSTAS!$C$2:$C$300,$B$21),2)),"") | ... AQ21: =IFERROR(IF(ROUND(SUMIF(RESPOSTAS!$C$2:$C$300,$B$21,Auxiliar!AR$1:AR$300)/COUNTIF(RESPOSTAS!$C$2:$C$300,$B$21),2)=0,"",ROUND(SUMIF(RESPOSTAS!$C$2:$C$300,$B$21,Auxiliar!AR$1:AR$300)/COUNTIF(RESPOSTAS!$C$2:$C$300,$B$21),2)),"")
